Workbook

Sheet Các loại báo cáo
B1: DANH SÁCH CÁC LOẠI BÁO CÁO CỬA DỰ ÁN
A3: STT | B3: Loại báo cáo | C3: Cấp độ | D3: Thời điểm xuất báo cáo
A5: 1 | B5: Báo cáo hoạt động và chỉ số | C5: Báo cáo CBO | D5: hàng tháng, 3 tháng, 6 tháng, 12 tháng
C6: Báo cáo tỉnh | D6: 3 tháng, 6 tháng, 12 tháng
C7: Báo cáo toàn dự án | D7: 6 tháng, 12 tháng
A8: 2 | B8: Báo cáo kết quả, chỉ số đột xuất | C8: Toàn dự án | D8: Theo yêu cầu của chương trình

Sheet Về nhà
C2: BÁO CÁO KẾT QUẢ HOẠT ĐỘNG
C3: Kỳ báo cáo: | F3: Tính theo nhóm KP hay nam/nữ/TG? | K3: Loại báo cáo
B4: # | C4: Thông tin báo cáo | E4: Tổng | F4: PUD | G4: PLHIV | H4: TG | I4: SW | J4: MSM | K4: Tháng | L4: Quý | M4: 6T | N4: 12T | O4: Nguồn số liệu | P4: Notes
B5: I | C5: THÔNG TIN CHUNG
B6: 1 | C6: Tổng số KH được chăm sóc từ đầu dự án | E6: {=SUMPRODUCT((DREAMH!$D$2:$D$766="Về nhà")*(DREAMH!$B$2:$B$766=""))} -> 153 | F6: {=SUMPRODUCT((DREAMH!$D$2:$D$766="Về nhà")*(DREAMH!$B$2:$B$766="")*(INDEX(DREAMH!$K$2:$K$766,MATCH(DREAMH!$A$2:$A$766,DREAMH!$A$2:$A$766,0))="Người sử dụng ma túy (PUD)"))} -> 77 | G6: {=SUMPRODUCT((DREAMH!$D$2:$D$766="Về nhà")*(DREAMH!$B$2:$B$766="")*(INDEX(DREAMH!$K$2:$K$766,MATCH(DREAMH!$A$2:$A$766,DREAMH!$A$2:$A$766,0))="Người sống chung với HIV (PLHIV)"))} -> 46 | H6: {=SUMPRODUCT((DREAMH!$D$2:$D$766="Về nhà")*(DREAMH!$B$2:$B$766="")*(INDEX(DREAMH!$K$2:$K$766,MATCH(DREAMH!$A$2:$A$766,DREAMH!$A$2:$A$766,0))="Người chuyển giới (TG)"))} -> 0 | I6: {=SUMPRODUCT((DREAMH!$D$2:$D$766="Về nhà")*(DREAMH!$B$2:$B$766="")*(INDEX(DREAMH!$K$2:$K$766,MATCH(DREAMH!$A$2:$A$766,DREAMH!$A$2:$A$766,0))="Người bán dâm (SW)"))} -> 29 | J6: {=SUMPRODUCT((DREAMH!$D$2:$D$766="Về nhà")*(DREAMH!$B$2:$B$766="")*(INDEX(DREAMH!$K$2:$K$766,MATCH(DREAMH!$A$2:$A$766,DREAMH!$A$2:$A$766,0))="Nam quan hệ tình dục đồng giới (MSM)"))} -> 1 | L6: x | M6: x | N6: x | O6: Dữ liệu từ các biểu mẫu (KH nhận bất cứ dịch vụ gì)
B7: 2 | C7: Tổng số KH được chăm sóc trong kỳ báo cáo | E7: {=SUMPRODUCT((DREAMH!$D$2:$D$766="Về nhà")*(DREAMH!$B$2:$B$766=""))} -> 153 | F7: {=SUMPRODUCT((DREAMH!$D$2:$D$766="Về nhà")*(DREAMH!$B$2:$B$766="")*(INDEX(DREAMH!$K$2:$K$766,MATCH(DREAMH!$A$2:$A$766,DREAMH!$A$2:$A$766,0))="Người sử dụng ma túy (PUD)"))} -> 77 | G7: {=SUMPRODUCT((DREAMH!$D$2:$D$766="Về nhà")*(DREAMH!$B$2:$B$766="")*(INDEX(DREAMH!$K$2:$K$766,MATCH(DREAMH!$A$2:$A$766,DREAMH!$A$2:$A$766,0))="Người sống chung với HIV (PLHIV)"))} -> 46 | H7: {=SUMPRODUCT((DREAMH!$D$2:$D$766="Về nhà")*(DREAMH!$B$2:$B$766="")*(INDEX(DREAMH!$K$2:$K$766,MATCH(DREAMH!$A$2:$A$766,DREAMH!$A$2:$A$766,0))="Người chuyển giới (TG)"))} -> 0 | I7: {=SUMPRODUCT((DREAMH!$D$2:$D$766="Về nhà")*(DREAMH!$B$2:$B$766="")*(INDEX(DREAMH!$K$2:$K$766,MATCH(DREAMH!$A$2:$A$766,DREAMH!$A$2:$A$766,0))="Người bán dâm (SW)"))} -> 29 | J7: {=SUMPRODUCT((DREAMH!$D$2:$D$766="Về nhà")*(DREAMH!$B$2:$B$766="")*(INDEX(DREAMH!$K$2:$K$766,MATCH(DREAMH!$A$2:$A$766,DREAMH!$A$2:$A$766,0))="Nam quan hệ tình dục đồng giới (MSM)"))} -> 1 | K7: x | L7: x | M7: x | N7: x | O7: Dữ liệu từ các biểu mẫu (KH nhận bất cứ dịch vụ gì)
B8: 3 | C8: Số KH mất dấu trong kỳ báo cáo | E8: {=SUMPRODUCT((DREAMH!$D$2:$D$766="Về nhà")*(DREAMH!$B$2:$B$766="F9. Theo dấu khách hàng")*(DREAMH!$JA$2:$JA$766="Chọn"))} -> 0 | F8: {=SUMPRODUCT((DREAMH!$D$2:$D$766="Về nhà")*(DREAMH!$B$2:$B$766="F9. Theo dấu khách hàng")*(DREAMH!$JA$2:$JA$766="Chọn")*(INDEX(DREAMH!$K$2:$K$766,MATCH(DREAMH!$A$2:$A$766,DREAMH!$A$2:$A$766,0))="Người sử dụng ma túy (PUD)"))} -> 0 | G8: {=SUMPRODUCT((DREAMH!$D$2:$D$766="Về nhà")*(DREAMH!$B$2:$B$766="F9. Theo dấu khách hàng")*(DREAMH!$JA$2:$JA$766="Chọn")*(INDEX(DREAMH!$K$2:$K$766,MATCH(DREAMH!$A$2:$A$766,DREAMH!$A$2:$A$766,0))="Người sống chung với HIV (PLHIV)"))} -> 0 | H8: {=SUMPRODUCT((DREAMH!$D$2:$D$766="Về nhà")*(DREAMH!$B$2:$B$766="F9. Theo dấu khách hàng")*(DREAMH!$JA$2:$JA$766="Chọn")*(INDEX(DREAMH!$K$2:$K$766,MATCH(DREAMH!$A$2:$A$766,DREAMH!$A$2:$A$766,0))="Người chuyển giới (TG)"))} -> 0 | I8: {=SUMPRODUCT((DREAMH!$D$2:$D$766="Về nhà")*(DREAMH!$B$2:$B$766="F9. Theo dấu khách hàng")*(DREAMH!$JA$2:$JA$766="Chọn")*(INDEX(DREAMH!$K$2:$K$766,MATCH(DREAMH!$A$2:$A$766,DREAMH!$A$2:$A$766,0))="Người bán dâm (SW)"))} -> 0 | J8: {=SUMPRODUCT((DREAMH!$D$2:$D$766="Về nhà")*(DREAMH!$B$2:$B$766="F9. Theo dấu khách hàng")*(DREAMH!$JA$2:$JA$766="Chọn")*(INDEX(DREAMH!$K$2:$K$766,MATCH(DREAMH!$A$2:$A$766,DREAMH!$A$2:$A$766,0))="Nam quan hệ tình dục đồng giới (MSM)"))} -> 0 | L8: x | M8: x | N8: x | O8: Dữ liệu từ biểu mẫu theo dấu KH | P8: Ghi nhận những KH được tính là mất dấu và được nhập liệu trên Redcap
B9: II | C9: HOẠT ĐỘNG TRUYỀN THÔNG
B10: 1 | C10: Số KH được tham gia truyền thông lần 1 | E10: {=SUMPRODUCT((DREAMH!$D$2:$D$766="Về nhà")*(DREAMH!$B$2:$B$766="F2. Truyền thông, sinh hoạt nhóm, vòng tròn chia sẻ, trị liệu nghệ thuật")*(DREAMH!$AA$2:$AA$766="Truyền thông")*(DREAMH!$C$2:$C$766=1))} -> 149 | F10: {=SUMPRODUCT((DREAMH!$D$2:$D$766="Về nhà")*(DREAMH!$B$2:$B$766="F2. Truyền thông, sinh hoạt nhóm, vòng tròn chia sẻ, trị liệu nghệ thuật")*(DREAMH!$AA$2:$AA$766="Truyền thông")*(DREAMH!$C$2:$C$766=1)*(INDEX(DREAMH!$K$2:$K$766,MATCH(DREAMH!$A$2:$A$766,DREAMH!$A$2:$A$766,0))="Người sử dụng ma túy (PUD)"))} -> 75 | G10: {=SUMPRODUCT((DREAMH!$D$2:$D$766="Về nhà")*(DREAMH!$B$2:$B$766="F2. Truyền thông, sinh hoạt nhóm, vòng tròn chia sẻ, trị liệu nghệ thuật")*(DREAMH!$AA$2:$AA$766="Truyền thông")*(DREAMH!$C$2:$C$766=1)*(INDEX(DREAMH!$K$2:$K$766,MATCH(DREAMH!$A$2:$A$766,DREAMH!$A$2:$A$766,0))="Người sống chung với HIV (PLHIV)"))} -> 45 | H10: {=SUMPRODUCT((DREAMH!$D$2:$D$766="Về nhà")*(DREAMH!$B$2:$B$766="F2. Truyền thông, sinh hoạt nhóm, vòng tròn chia sẻ, trị liệu nghệ thuật")*(DREAMH!$AA$2:$AA$766="Truyền thông")*(DREAMH!$C$2:$C$766=1)*(INDEX(DREAMH!$K$2:$K$766,MATCH(DREAMH!$A$2:$A$766,DREAMH!$A$2:$A$766,0))="Người chuyển giới (TG)"))} -> 0 | I10: {=SUMPRODUCT((DREAMH!$D$2:$D$766="Về nhà")*(DREAMH!$B$2:$B$766="F2. Truyền thông, sinh hoạt nhóm, vòng tròn chia sẻ, trị liệu nghệ thuật")*(DREAMH!$AA$2:$AA$766="Truyền thông")*(DREAMH!$C$2:$C$766=1)*(INDEX(DREAMH!$K$2:$K$766,MATCH(DREAMH!$A$2:$A$766,DREAMH!$A$2:$A$766,0))="Người bán dâm (SW)"))} -> 28 | J10: {=SUMPRODUCT((DREAMH!$D$2:$D$766="Về nhà")*(DREAMH!$B$2:$B$766="F2. Truyền thông, sinh hoạt nhóm, vòng tròn chia sẻ, trị liệu nghệ thuật")*(DREAMH!$AA$2:$AA$766="Truyền thông")*(DREAMH!$C$2:$C$766=1)*(INDEX(DREAMH!$K$2:$K$766,MATCH(DREAMH!$A$2:$A$766,DREAMH!$A$2:$A$766,0))="Nam quan hệ tình dục đồng giới (MSM)"))} -> 1 | K10: x | L10: x | M10: x | N10: x | O10: Dữ liệu từ biểu mẫu truyền thông
B11: 2 | C11: Số KH được tham gia truyền thông lần 2 | E11: {=SUMPRODUCT((DREAMH!$D$2:$D$766="Về nhà")*(DREAMH!$B$2:$B$766="F2. Truyền thông, sinh hoạt nhóm, vòng tròn chia sẻ, trị liệu nghệ thuật")*(DREAMH!$AA$2:$AA$766="Truyền thông")*(DREAMH!$C$2:$C$766=2))} -> 0 | F11: {=SUMPRODUCT((DREAMH!$D$2:$D$766="Về nhà")*(DREAMH!$B$2:$B$766="F2. Truyền thông, sinh hoạt nhóm, vòng tròn chia sẻ, trị liệu nghệ thuật")*(DREAMH!$AA$2:$AA$766="Truyền thông")*(DREAMH!$C$2:$C$766=2)*(INDEX(DREAMH!$K$2:$K$766,MATCH(DREAMH!$A$2:$A$766,DREAMH!$A$2:$A$766,0))="Người sử dụng ma túy (PUD)"))} -> 0 | G11: {=SUMPRODUCT((DREAMH!$D$2:$D$766="Về nhà")*(DREAMH!$B$2:$B$766="F2. Truyền thông, sinh hoạt nhóm, vòng tròn chia sẻ, trị liệu nghệ thuật")*(DREAMH!$AA$2:$AA$766="Truyền thông")*(DREAMH!$C$2:$C$766=2)*(INDEX(DREAMH!$K$2:$K$766,MATCH(DREAMH!$A$2:$A$766,DREAMH!$A$2:$A$766,0))="Người sống chung với HIV (PLHIV)"))} -> 0 | H11: {=SUMPRODUCT((DREAMH!$D$2:$D$766="Về nhà")*(DREAMH!$B$2:$B$766="F2. Truyền thông, sinh hoạt nhóm, vòng tròn chia sẻ, trị liệu nghệ thuật")*(DREAMH!$AA$2:$AA$766="Truyền thông")*(DREAMH!$C$2:$C$766=2)*(INDEX(DREAMH!$K$2:$K$766,MATCH(DREAMH!$A$2:$A$766,DREAMH!$A$2:$A$766,0))="Người chuyển giới (TG)"))} -> 0 | I11: {=SUMPRODUCT((DREAMH!$D$2:$D$766="Về nhà")*(DREAMH!$B$2:$B$766="F2. Truyền thông, sinh hoạt nhóm, vòng tròn chia sẻ, trị liệu nghệ thuật")*(DREAMH!$AA$2:$AA$766="Truyền thông")*(DREAMH!$C$2:$C$766=2)*(INDEX(DREAMH!$K$2:$K$766,MATCH(DREAMH!$A$2:$A$766,DREAMH!$A$2:$A$766,0))="Người bán dâm (SW)"))} -> 0 | J11: {=SUMPRODUCT((DREAMH!$D$2:$D$766="Về nhà")*(DREAMH!$B$2:$B$766="F2. Truyền thông, sinh hoạt nhóm, vòng tròn chia sẻ, trị liệu nghệ thuật")*(DREAMH!$AA$2:$AA$766="Truyền thông")*(DREAMH!$C$2:$C$766=2)*(INDEX(DREAMH!$K$2:$K$766,MATCH(DREAMH!$A$2:$A$766,DREAMH!$A$2:$A$766,0))="Nam quan hệ tình dục đồng giới (MSM)"))} -> 0 | K11: x | L11: x | M11: x | N11: x
B12: 3 | C12: Tổng số lượt KH tham gia truyền thông | E12: {=SUMPRODUCT((DREAMH!$D$2:$D$766="Về nhà")*(DREAMH!$B$2:$B$766="F2. Truyền thông, sinh hoạt nhóm, vòng tròn chia sẻ, trị liệu nghệ thuật")*(DREAMH!$AA$2:$AA$766="Truyền thông"))} -> 149 | F12: {=SUMPRODUCT((DREAMH!$D$2:$D$766="Về nhà")*(DREAMH!$B$2:$B$766="F2. Truyền thông, sinh hoạt nhóm, vòng tròn chia sẻ, trị liệu nghệ thuật")*(DREAMH!$AA$2:$AA$766="Truyền thông")*(INDEX(DREAMH!$K$2:$K$766,MATCH(DREAMH!$A$2:$A$766,DREAMH!$A$2:$A$766,0))="Người sử dụng ma túy (PUD)"))} -> 75 | G12: {=SUMPRODUCT((DREAMH!$D$2:$D$766="Về nhà")*(DREAMH!$B$2:$B$766="F2. Truyền thông, sinh hoạt nhóm, vòng tròn chia sẻ, trị liệu nghệ thuật")*(DREAMH!$AA$2:$AA$766="Truyền thông")*(INDEX(DREAMH!$K$2:$K$766,MATCH(DREAMH!$A$2:$A$766,DREAMH!$A$2:$A$766,0))="Người sống chung với HIV (PLHIV)"))} -> 45 | H12: {=SUMPRODUCT((DREAMH!$D$2:$D$766="Về nhà")*(DREAMH!$B$2:$B$766="F2. Truyền thông, sinh hoạt nhóm, vòng tròn chia sẻ, trị liệu nghệ thuật")*(DREAMH!$AA$2:$AA$766="Truyền thông")*(INDEX(DREAMH!$K$2:$K$766,MATCH(DREAMH!$A$2:$A$766,DREAMH!$A$2:$A$766,0))="Người chuyển giới (TG)"))} -> 0 | I12: {=SUMPRODUCT((DREAMH!$D$2:$D$766="Về nhà")*(DREAMH!$B$2:$B$766="F2. Truyền thông, sinh hoạt nhóm, vòng tròn chia sẻ, trị liệu nghệ thuật")*(DREAMH!$AA$2:$AA$766="Truyền thông")*(INDEX(DREAMH!$K$2:$K$766,MATCH(DREAMH!$A$2:$A$766,DREAMH!$A$2:$A$766,0))="Người bán dâm (SW)"))} -> 28 | J12: {=SUMPRODUCT((DREAMH!$D$2:$D$766="Về nhà")*(DREAMH!$B$2:$B$766="F2. Truyền thông, sinh hoạt nhóm, vòng tròn chia sẻ, trị liệu nghệ thuật")*(DREAMH!$AA$2:$AA$766="Truyền thông")*(INDEX(DREAMH!$K$2:$K$766,MATCH(DREAMH!$A$2:$A$766,DREAMH!$A$2:$A$766,0))="Nam quan hệ tình dục đồng giới (MSM)"))} -> 1 | K12: x | L12: x | M12: x | N12: x
B13: III | C13: SÀNG LỌC BẢNG HỎI QST VÀ CHUYỂN GỬI KHÁM, ĐIỀU TRỊ SKTT | O13: Dữ liệu từ bảng hỏi QST
B14: 1 | C14: Số KH được sàng lọc bảng hỏi QST lần 1 | E14: {=SUMPRODUCT((DREAMH!$D$2:$D$766="Về nhà")*(DREAMH!$B$2:$B$766="F3. Bảng hỏi sàng lọc sức khoẻ tâm thần (QST)")*(DREAMH!$C$2:$C$766=1))} -> 134 | F14: {=SUMPRODUCT((DREAMH!$D$2:$D$766="Về nhà")*(DREAMH!$B$2:$B$766="F3. Bảng hỏi sàng lọc sức khoẻ tâm thần (QST)")*(DREAMH!$C$2:$C$766=1)*(INDEX(DREAMH!$K$2:$K$766,MATCH(DREAMH!$A$2:$A$766,DREAMH!$A$2:$A$766,0))="Người sử dụng ma túy (PUD)"))} -> 66 | G14: {=SUMPRODUCT((DREAMH!$D$2:$D$766="Về nhà")*(DREAMH!$B$2:$B$766="F3. Bảng hỏi sàng lọc sức khoẻ tâm thần (QST)")*(DREAMH!$C$2:$C$766=1)*(INDEX(DREAMH!$K$2:$K$766,MATCH(DREAMH!$A$2:$A$766,DREAMH!$A$2:$A$766,0))="Người sống chung với HIV (PLHIV)"))} -> 42 | H14: {=SUMPRODUCT((DREAMH!$D$2:$D$766="Về nhà")*(DREAMH!$B$2:$B$766="F3. Bảng hỏi sàng lọc sức khoẻ tâm thần (QST)")*(DREAMH!$C$2:$C$766=1)*(INDEX(DREAMH!$K$2:$K$766,MATCH(DREAMH!$A$2:$A$766,DREAMH!$A$2:$A$766,0))="Người chuyển giới (TG)"))} -> 0 | I14: {=SUMPRODUCT((DREAMH!$D$2:$D$766="Về nhà")*(DREAMH!$B$2:$B$766="F3. Bảng hỏi sàng lọc sức khoẻ tâm thần (QST)")*(DREAMH!$C$2:$C$766=1)*(INDEX(DREAMH!$K$2:$K$766,MATCH(DREAMH!$A$2:$A$766,DREAMH!$A$2:$A$766,0))="Người bán dâm (SW)"))} -> 25 | J14: {=SUMPRODUCT((DREAMH!$D$2:$D$766="Về nhà")*(DREAMH!$B$2:$B$766="F3. Bảng hỏi sàng lọc sức khoẻ tâm thần (QST)")*(DREAMH!$C$2:$C$766=1)*(INDEX(DREAMH!$K$2:$K$766,MATCH(DREAMH!$A$2:$A$766,DREAMH!$A$2:$A$766,0))="Nam quan hệ tình dục đồng giới (MSM)"))} -> 1 | K14: x | L14: x | M14: x | N14: x
C15: Kết quả sàng lọc QST lần đầu | D15: Mức 1 (>=8) | E15: {=SUMPRODUCT((DREAMH!$D$2:$D$766="Về nhà")*(DREAMH!$B$2:$B$766="F3. Bảng hỏi sàng lọc sức khoẻ tâm thần (QST)")*(DREAMH!$C$2:$C$766=1)*(DREAMH!$BC$2:$BC$766>=8))} -> 19 | F15: {=SUMPRODUCT((DREAMH!$D$2:$D$766="Về nhà")*(DREAMH!$B$2:$B$766="F3. Bảng hỏi sàng lọc sức khoẻ tâm thần (QST)")*(DREAMH!$C$2:$C$766=1)*(DREAMH!$BC$2:$BC$766>=8)*(INDEX(DREAMH!$K$2:$K$766,MATCH(DREAMH!$A$2:$A$766,DREAMH!$A$2:$A$766,0))="Người sử dụng ma túy (PUD)"))} -> 15 | G15: {=SUMPRODUCT((DREAMH!$D$2:$D$766="Về nhà")*(DREAMH!$B$2:$B$766="F3. Bảng hỏi sàng lọc sức khoẻ tâm thần (QST)")*(DREAMH!$C$2:$C$766=1)*(DREAMH!$BC$2:$BC$766>=8)*(INDEX(DREAMH!$K$2:$K$766,MATCH(DREAMH!$A$2:$A$766,DREAMH!$A$2:$A$766,0))="Người sống chung với HIV (PLHIV)"))} -> 4 | H15: {=SUMPRODUCT((DREAMH!$D$2:$D$766="Về nhà")*(DREAMH!$B$2:$B$766="F3. Bảng hỏi sàng lọc sức khoẻ tâm thần (QST)")*(DREAMH!$C$2:$C$766=1)*(DREAMH!$BC$2:$BC$766>=8)*(INDEX(DREAMH!$K$2:$K$766,MATCH(DREAMH!$A$2:$A$766,DREAMH!$A$2:$A$766,0))="Người chuyển giới (TG)"))} -> 0 | I15: {=SUMPRODUCT((DREAMH!$D$2:$D$766="Về nhà")*(DREAMH!$B$2:$B$766="F3. Bảng hỏi sàng lọc sức khoẻ tâm thần (QST)")*(DREAMH!$C$2:$C$766=1)*(DREAMH!$BC$2:$BC$766>=8)*(INDEX(DREAMH!$K$2:$K$766,MATCH(DREAMH!$A$2:$A$766,DREAMH!$A$2:$A$766,0))="Người bán dâm (SW)"))} -> 0 | J15: {=SUMPRODUCT((DREAMH!$D$2:$D$766="Về nhà")*(DREAMH!$B$2:$B$766="F3. Bảng hỏi sàng lọc sức khoẻ tâm thần (QST)")*(DREAMH!$C$2:$C$766=1)*(DREAMH!$BC$2:$BC$766>=8)*(INDEX(DREAMH!$K$2:$K$766,MATCH(DREAMH!$A$2:$A$766,DREAMH!$A$2:$A$766,0))="Nam quan hệ tình dục đồng giới (MSM)"))} -> 0 | K15: x | L15: x | M15: x | N15: x
D16: Mức 2 (6 - 7) | E16: {=SUMPRODUCT((DREAMH!$D$2:$D$766="Về nhà")*(DREAMH!$B$2:$B$766="F3. Bảng hỏi sàng lọc sức khoẻ tâm thần (QST)")*(DREAMH!$C$2:$C$766=1)*(DREAMH!$BC$2:$BC$766>=6)*(DREAMH!$BC$2:$BC$766<=7))} -> 39 | F16: {=SUMPRODUCT((DREAMH!$D$2:$D$766="Về nhà")*(DREAMH!$B$2:$B$766="F3. Bảng hỏi sàng lọc sức khoẻ tâm thần (QST)")*(DREAMH!$C$2:$C$766=1)*(DREAMH!$BC$2:$BC$766>=6)*(DREAMH!$BC$2:$BC$766<=7)*(INDEX(DREAMH!$K$2:$K$766,MATCH(DREAMH!$A$2:$A$766,DREAMH!$A$2:$A$766,0))="Người sử dụng ma túy (PUD)"))} -> 19 | G16: {=SUMPRODUCT((DREAMH!$D$2:$D$766="Về nhà")*(DREAMH!$B$2:$B$766="F3. Bảng hỏi sàng lọc sức khoẻ tâm thần (QST)")*(DREAMH!$C$2:$C$766=1)*(DREAMH!$BC$2:$BC$766>=6)*(DREAMH!$BC$2:$BC$766<=7)*(INDEX(DREAMH!$K$2:$K$766,MATCH(DREAMH!$A$2:$A$766,DREAMH!$A$2:$A$766,0))="Người sống chung với HIV (PLHIV)"))} -> 9 | H16: {=SUMPRODUCT((DREAMH!$D$2:$D$766="Về nhà")*(DREAMH!$B$2:$B$766="F3. Bảng hỏi sàng lọc sức khoẻ tâm thần (QST)")*(DREAMH!$C$2:$C$766=1)*(DREAMH!$BC$2:$BC$766>=6)*(DREAMH!$BC$2:$BC$766<=7)*(INDEX(DREAMH!$K$2:$K$766,MATCH(DREAMH!$A$2:$A$766,DREAMH!$A$2:$A$766,0))="Người chuyển giới (TG)"))} -> 0 | I16: {=SUMPRODUCT((DREAMH!$D$2:$D$766="Về nhà")*(DREAMH!$B$2:$B$766="F3. Bảng hỏi sàng lọc sức khoẻ tâm thần (QST)")*(DREAMH!$C$2:$C$766=1)*(DREAMH!$BC$2:$BC$766>=6)*(DREAMH!$BC$2:$BC$766<=7)*(INDEX(DREAMH!$K$2:$K$766,MATCH(DREAMH!$A$2:$A$766,DREAMH!$A$2:$A$766,0))="Người bán dâm (SW)"))} -> 10 | J16: {=SUMPRODUCT((DREAMH!$D$2:$D$766="Về nhà")*(DREAMH!$B$2:$B$766="F3. Bảng hỏi sàng lọc sức khoẻ tâm thần (QST)")*(DREAMH!$C$2:$C$766=1)*(DREAMH!$BC$2:$BC$766>=6)*(DREAMH!$BC$2:$BC$766<=7)*(INDEX(DREAMH!$K$2:$K$766,MATCH(DREAMH!$A$2:$A$766,DREAMH!$A$2:$A$766,0))="Nam quan hệ tình dục đồng giới (MSM)"))} -> 1 | K16: x | L16: x | M16: x | N16: x
D17: Mức 3 (4 - 5) | E17: {=SUMPRODUCT((DREAMH!$D$2:$D$766="Về nhà")*(DREAMH!$B$2:$B$766="F3. Bảng hỏi sàng lọc sức khoẻ tâm thần (QST)")*(DREAMH!$C$2:$C$766=1)*(DREAMH!$BC$2:$BC$766>=4)*(DREAMH!$BC$2:$BC$766<=5))} -> 42 | F17: {=SUMPRODUCT((DREAMH!$D$2:$D$766="Về nhà")*(DREAMH!$B$2:$B$766="F3. Bảng hỏi sàng lọc sức khoẻ tâm thần (QST)")*(DREAMH!$C$2:$C$766=1)*(DREAMH!$BC$2:$BC$766>=4)*(DREAMH!$BC$2:$BC$766<=5)*(INDEX(DREAMH!$K$2:$K$766,MATCH(DREAMH!$A$2:$A$766,DREAMH!$A$2:$A$766,0))="Người sử dụng ma túy (PUD)"))} -> 21 | G17: {=SUMPRODUCT((DREAMH!$D$2:$D$766="Về nhà")*(DREAMH!$B$2:$B$766="F3. Bảng hỏi sàng lọc sức khoẻ tâm thần (QST)")*(DREAMH!$C$2:$C$766=1)*(DREAMH!$BC$2:$BC$766>=4)*(DREAMH!$BC$2:$BC$766<=5)*(INDEX(DREAMH!$K$2:$K$766,MATCH(DREAMH!$A$2:$A$766,DREAMH!$A$2:$A$766,0))="Người sống chung với HIV (PLHIV)"))} -> 16 | H17: {=SUMPRODUCT((DREAMH!$D$2:$D$766="Về nhà")*(DREAMH!$B$2:$B$766="F3. Bảng hỏi sàng lọc sức khoẻ tâm thần (QST)")*(DREAMH!$C$2:$C$766=1)*(DREAMH!$BC$2:$BC$766>=4)*(DREAMH!$BC$2:$BC$766<=5)*(INDEX(DREAMH!$K$2:$K$766,MATCH(DREAMH!$A$2:$A$766,DREAMH!$A$2:$A$766,0))="Người chuyển giới (TG)"))} -> 0 | I17: {=SUMPRODUCT((DREAMH!$D$2:$D$766="Về nhà")*(DREAMH!$B$2:$B$766="F3. Bảng hỏi sàng lọc sức khoẻ tâm thần (QST)")*(DREAMH!$C$2:$C$766=1)*(DREAMH!$BC$2:$BC$766>=4)*(DREAMH!$BC$2:$BC$766<=5)*(INDEX(DREAMH!$K$2:$K$766,MATCH(DREAMH!$A$2:$A$766,DREAMH!$A$2:$A$766,0))="Người bán dâm (SW)"))} -> 5 | J17: {=SUMPRODUCT((DREAMH!$D$2:$D$766="Về nhà")*(DREAMH!$B$2:$B$766="F3. Bảng hỏi sàng lọc sức khoẻ tâm thần (QST)")*(DREAMH!$C$2:$C$766=1)*(DREAMH!$BC$2:$BC$766>=4)*(DREAMH!$BC$2:$BC$766<=5)*(INDEX(DREAMH!$K$2:$K$766,MATCH(DREAMH!$A$2:$A$766,DREAMH!$A$2:$A$766,0))="Nam quan hệ tình dục đồng giới (MSM)"))} -> 0 | K17: x | L17: x | M17: x | N17: x
D18: Mức 4 (<4) | E18: {=SUMPRODUCT((DREAMH!$D$2:$D$766="Về nhà")*(DREAMH!$B$2:$B$766="F3. Bảng hỏi sàng lọc sức khoẻ tâm thần (QST)")*(DREAMH!$C$2:$C$766=1)*(DREAMH!$BC$2:$BC$766<4))} -> 34 | F18: {=SUMPRODUCT((DREAMH!$D$2:$D$766="Về nhà")*(DREAMH!$B$2:$B$766="F3. Bảng hỏi sàng lọc sức khoẻ tâm thần (QST)")*(DREAMH!$C$2:$C$766=1)*(DREAMH!$BC$2:$BC$766<4)*(INDEX(DREAMH!$K$2:$K$766,MATCH(DREAMH!$A$2:$A$766,DREAMH!$A$2:$A$766,0))="Người sử dụng ma túy (PUD)"))} -> 11 | G18: {=SUMPRODUCT((DREAMH!$D$2:$D$766="Về nhà")*(DREAMH!$B$2:$B$766="F3. Bảng hỏi sàng lọc sức khoẻ tâm thần (QST)")*(DREAMH!$C$2:$C$766=1)*(DREAMH!$BC$2:$BC$766<4)*(INDEX(DREAMH!$K$2:$K$766,MATCH(DREAMH!$A$2:$A$766,DREAMH!$A$2:$A$766,0))="Người sống chung với HIV (PLHIV)"))} -> 13 | H18: {=SUMPRODUCT((DREAMH!$D$2:$D$766="Về nhà")*(DREAMH!$B$2:$B$766="F3. Bảng hỏi sàng lọc sức khoẻ tâm thần (QST)")*(DREAMH!$C$2:$C$766=1)*(DREAMH!$BC$2:$BC$766<4)*(INDEX(DREAMH!$K$2:$K$766,MATCH(DREAMH!$A$2:$A$766,DREAMH!$A$2:$A$766,0))="Người chuyển giới (TG)"))} -> 0 | I18: {=SUMPRODUCT((DREAMH!$D$2:$D$766="Về nhà")*(DREAMH!$B$2:$B$766="F3. Bảng hỏi sàng lọc sức khoẻ tâm thần (QST)")*(DREAMH!$C$2:$C$766=1)*(DREAMH!$BC$2:$BC$766<4)*(INDEX(DREAMH!$K$2:$K$766,MATCH(DREAMH!$A$2:$A$766,DREAMH!$A$2:$A$766,0))="Người bán dâm (SW)"))} -> 10 | J18: {=SUMPRODUCT((DREAMH!$D$2:$D$766="Về nhà")*(DREAMH!$B$2:$B$766="F3. Bảng hỏi sàng lọc sức khoẻ tâm thần (QST)")*(DREAMH!$C$2:$C$766=1)*(DREAMH!$BC$2:$BC$766<4)*(INDEX(DREAMH!$K$2:$K$766,MATCH(DREAMH!$A$2:$A$766,DREAMH!$A$2:$A$766,0))="Nam quan hệ tình dục đồng giới (MSM)"))} -> 0 | K18: x | L18: x | M18: x | N18: x
B19: 2 | C19: Số KH được sàng lọc lại bảng hỏi QST (từ lần 2 trở đi) | E19: {=SUMPRODUCT((DREAMH!$D$2:$D$766="Về nhà")*(DREAMH!$B$2:$B$766="F3. Bảng hỏi sàng lọc sức khoẻ tâm thần (QST)")*(DREAMH!$C$2:$C$766>=2))} -> 0 | F19: {=SUMPRODUCT((DREAMH!$D$2:$D$766="Về nhà")*(DREAMH!$B$2:$B$766="F3. Bảng hỏi sàng lọc sức khoẻ tâm thần (QST)")*(DREAMH!$C$2:$C$766>=2)*(INDEX(DREAMH!$K$2:$K$766,MATCH(DREAMH!$A$2:$A$766,DREAMH!$A$2:$A$766,0))="Người sử dụng ma túy (PUD)"))} -> 0 | G19: {=SUMPRODUCT((DREAMH!$D$2:$D$766="Về nhà")*(DREAMH!$B$2:$B$766="F3. Bảng hỏi sàng lọc sức khoẻ tâm thần (QST)")*(DREAMH!$C$2:$C$766>=2)*(INDEX(DREAMH!$K$2:$K$766,MATCH(DREAMH!$A$2:$A$766,DREAMH!$A$2:$A$766,0))="Người sống chung với HIV (PLHIV)"))} -> 0 | H19: {=SUMPRODUCT((DREAMH!$D$2:$D$766="Về nhà")*(DREAMH!$B$2:$B$766="F3. Bảng hỏi sàng lọc sức khoẻ tâm thần (QST)")*(DREAMH!$C$2:$C$766>=2)*(INDEX(DREAMH!$K$2:$K$766,MATCH(DREAMH!$A$2:$A$766,DREAMH!$A$2:$A$766,0))="Người chuyển giới (TG)"))} -> 0 | I19: {=SUMPRODUCT((DREAMH!$D$2:$D$766="Về nhà")*(DREAMH!$B$2:$B$766="F3. Bảng hỏi sàng lọc sức khoẻ tâm thần (QST)")*(DREAMH!$C$2:$C$766>=2)*(INDEX(DREAMH!$K$2:$K$766,MATCH(DREAMH!$A$2:$A$766,DREAMH!$A$2:$A$766,0))="Người bán dâm (SW)"))} -> 0 | J19: {=SUMPRODUCT((DREAMH!$D$2:$D$766="Về nhà")*(DREAMH!$B$2:$B$766="F3. Bảng hỏi sàng lọc sức khoẻ tâm thần (QST)")*(DREAMH!$C$2:$C$766>=2)*(INDEX(DREAMH!$K$2:$K$766,MATCH(DREAMH!$A$2:$A$766,DREAMH!$A$2:$A$766,0))="Nam quan hệ tình dục đồng giới (MSM)"))} -> 0 | K19: x | L19: x | M19: x | N19: x | O19: Dữ liệu từ bảng hỏi lại QST
C20: Kết quả sàng lọc lại QST | D20: Mức 1 (>=8) | E20: {=SUMPRODUCT((DREAMH!$D$2:$D$766="Về nhà")*(DREAMH!$B$2:$B$766="F3. Bảng hỏi sàng lọc sức khoẻ tâm thần (QST)")*(DREAMH!$C$2:$C$766>=2)*(DREAMH!$BC$2:$BC$766>=8))} -> 0 | F20: {=SUMPRODUCT((DREAMH!$D$2:$D$766="Về nhà")*(DREAMH!$B$2:$B$766="F3. Bảng hỏi sàng lọc sức khoẻ tâm thần (QST)")*(DREAMH!$C$2:$C$766>=2)*(DREAMH!$BC$2:$BC$766>=8)*(INDEX(DREAMH!$K$2:$K$766,MATCH(DREAMH!$A$2:$A$766,DREAMH!$A$2:$A$766,0))="Người sử dụng ma túy (PUD)"))} -> 0 | G20: {=SUMPRODUCT((DREAMH!$D$2:$D$766="Về nhà")*(DREAMH!$B$2:$B$766="F3. Bảng hỏi sàng lọc sức khoẻ tâm thần (QST)")*(DREAMH!$C$2:$C$766>=2)*(DREAMH!$BC$2:$BC$766>=8)*(INDEX(DREAMH!$K$2:$K$766,MATCH(DREAMH!$A$2:$A$766,DREAMH!$A$2:$A$766,0))="Người sống chung với HIV (PLHIV)"))} -> 0 | H20: {=SUMPRODUCT((DREAMH!$D$2:$D$766="Về nhà")*(DREAMH!$B$2:$B$766="F3. Bảng hỏi sàng lọc sức khoẻ tâm thần (QST)")*(DREAMH!$C$2:$C$766>=2)*(DREAMH!$BC$2:$BC$766>=8)*(INDEX(DREAMH!$K$2:$K$766,MATCH(DREAMH!$A$2:$A$766,DREAMH!$A$2:$A$766,0))="Người chuyển giới (TG)"))} -> 0 | I20: {=SUMPRODUCT((DREAMH!$D$2:$D$766="Về nhà")*(DREAMH!$B$2:$B$766="F3. Bảng hỏi sàng lọc sức khoẻ tâm thần (QST)")*(DREAMH!$C$2:$C$766>=2)*(DREAMH!$BC$2:$BC$766>=8)*(INDEX(DREAMH!$K$2:$K$766,MATCH(DREAMH!$A$2:$A$766,DREAMH!$A$2:$A$766,0))="Người bán dâm (SW)"))} -> 0 | J20: {=SUMPRODUCT((DREAMH!$D$2:$D$766="Về nhà")*(DREAMH!$B$2:$B$766="F3. Bảng hỏi sàng lọc sức khoẻ tâm thần (QST)")*(DREAMH!$C$2:$C$766>=2)*(DREAMH!$BC$2:$BC$766>=8)*(INDEX(DREAMH!$K$2:$K$766,MATCH(DREAMH!$A$2:$A$766,DREAMH!$A$2:$A$766,0))="Nam quan hệ tình dục đồng giới (MSM)"))} -> 0 | K20: x | L20: x | M20: x | N20: x
D21: Mức 2 (6 - 7) | E21: {=SUMPRODUCT((DREAMH!$D$2:$D$766="Về nhà")*(DREAMH!$B$2:$B$766="F3. Bảng hỏi sàng lọc sức khoẻ tâm thần (QST)")*(DREAMH!$C$2:$C$766>=2)*(DREAMH!$BC$2:$BC$766>=6)*(DREAMH!$BC$2:$BC$766<=7))} -> 0 | F21: {=SUMPRODUCT((DREAMH!$D$2:$D$766="Về nhà")*(DREAMH!$B$2:$B$766="F3. Bảng hỏi sàng lọc sức khoẻ tâm thần (QST)")*(DREAMH!$C$2:$C$766>=2)*(DREAMH!$BC$2:$BC$766>=6)*(DREAMH!$BC$2:$BC$766<=7)*(INDEX(DREAMH!$K$2:$K$766,MATCH(DREAMH!$A$2:$A$766,DREAMH!$A$2:$A$766,0))="Người sử dụng ma túy (PUD)"))} -> 0 | G21: {=SUMPRODUCT((DREAMH!$D$2:$D$766="Về nhà")*(DREAMH!$B$2:$B$766="F3. Bảng hỏi sàng lọc sức khoẻ tâm thần (QST)")*(DREAMH!$C$2:$C$766>=2)*(DREAMH!$BC$2:$BC$766>=6)*(DREAMH!$BC$2:$BC$766<=7)*(INDEX(DREAMH!$K$2:$K$766,MATCH(DREAMH!$A$2:$A$766,DREAMH!$A$2:$A$766,0))="Người sống chung với HIV (PLHIV)"))} -> 0 | H21: {=SUMPRODUCT((DREAMH!$D$2:$D$766="Về nhà")*(DREAMH!$B$2:$B$766="F3. Bảng hỏi sàng lọc sức khoẻ tâm thần (QST)")*(DREAMH!$C$2:$C$766>=2)*(DREAMH!$BC$2:$BC$766>=6)*(DREAMH!$BC$2:$BC$766<=7)*(INDEX(DREAMH!$K$2:$K$766,MATCH(DREAMH!$A$2:$A$766,DREAMH!$A$2:$A$766,0))="Người chuyển giới (TG)"))} -> 0 | I21: {=SUMPRODUCT((DREAMH!$D$2:$D$766="Về nhà")*(DREAMH!$B$2:$B$766="F3. Bảng hỏi sàng lọc sức khoẻ tâm thần (QST)")*(DREAMH!$C$2:$C$766>=2)*(DREAMH!$BC$2:$BC$766>=6)*(DREAMH!$BC$2:$BC$766<=7)*(INDEX(DREAMH!$K$2:$K$766,MATCH(DREAMH!$A$2:$A$766,DREAMH!$A$2:$A$766,0))="Người bán dâm (SW)"))} -> 0 | J21: {=SUMPRODUCT((DREAMH!$D$2:$D$766="Về nhà")*(DREAMH!$B$2:$B$766="F3. Bảng hỏi sàng lọc sức khoẻ tâm thần (QST)")*(DREAMH!$C$2:$C$766>=2)*(DREAMH!$BC$2:$BC$766>=6)*(DREAMH!$BC$2:$BC$766<=7)*(INDEX(DREAMH!$K$2:$K$766,MATCH(DREAMH!$A$2:$A$766,DREAMH!$A$2:$A$766,0))="Nam quan hệ tình dục đồng giới (MSM)"))} -> 0 | K21: x | L21: x | M21: x | N21: x
D22: Mức 3 (4 - 5) | E22: {=SUMPRODUCT((DREAMH!$D$2:$D$766="Về nhà")*(DREAMH!$B$2:$B$766="F3. Bảng hỏi sàng lọc sức khoẻ tâm thần (QST)")*(DREAMH!$C$2:$C$766>=2)*(DREAMH!$BC$2:$BC$766>=4)*(DREAMH!$BC$2:$BC$766<=5))} -> 0 | F22: {=SUMPRODUCT((DREAMH!$D$2:$D$766="Về nhà")*(DREAMH!$B$2:$B$766="F3. Bảng hỏi sàng lọc sức khoẻ tâm thần (QST)")*(DREAMH!$C$2:$C$766>=2)*(DREAMH!$BC$2:$BC$766>=4)*(DREAMH!$BC$2:$BC$766<=5)*(INDEX(DREAMH!$K$2:$K$766,MATCH(DREAMH!$A$2:$A$766,DREAMH!$A$2:$A$766,0))="Người sử dụng ma túy (PUD)"))} -> 0 | G22: {=SUMPRODUCT((DREAMH!$D$2:$D$766="Về nhà")*(DREAMH!$B$2:$B$766="F3. Bảng hỏi sàng lọc sức khoẻ tâm thần (QST)")*(DREAMH!$C$2:$C$766>=2)*(DREAMH!$BC$2:$BC$766>=4)*(DREAMH!$BC$2:$BC$766<=5)*(INDEX(DREAMH!$K$2:$K$766,MATCH(DREAMH!$A$2:$A$766,DREAMH!$A$2:$A$766,0))="Người sống chung với HIV (PLHIV)"))} -> 0 | H22: {=SUMPRODUCT((DREAMH!$D$2:$D$766="Về nhà")*(DREAMH!$B$2:$B$766="F3. Bảng hỏi sàng lọc sức khoẻ tâm thần (QST)")*(DREAMH!$C$2:$C$766>=2)*(DREAMH!$BC$2:$BC$766>=4)*(DREAMH!$BC$2:$BC$766<=5)*(INDEX(DREAMH!$K$2:$K$766,MATCH(DREAMH!$A$2:$A$766,DREAMH!$A$2:$A$766,0))="Người chuyển giới (TG)"))} -> 0 | I22: {=SUMPRODUCT((DREAMH!$D$2:$D$766="Về nhà")*(DREAMH!$B$2:$B$766="F3. Bảng hỏi sàng lọc sức khoẻ tâm thần (QST)")*(DREAMH!$C$2:$C$766>=2)*(DREAMH!$BC$2:$BC$766>=4)*(DREAMH!$BC$2:$BC$766<=5)*(INDEX(DREAMH!$K$2:$K$766,MATCH(DREAMH!$A$2:$A$766,DREAMH!$A$2:$A$766,0))="Người bán dâm (SW)"))} -> 0 | J22: {=SUMPRODUCT((DREAMH!$D$2:$D$766="Về nhà")*(DREAMH!$B$2:$B$766="F3. Bảng hỏi sàng lọc sức khoẻ tâm thần (QST)")*(DREAMH!$C$2:$C$766>=2)*(DREAMH!$BC$2:$BC$766>=4)*(DREAMH!$BC$2:$BC$766<=5)*(INDEX(DREAMH!$K$2:$K$766,MATCH(DREAMH!$A$2:$A$766,DREAMH!$A$2:$A$766,0))="Nam quan hệ tình dục đồng giới (MSM)"))} -> 0 | K22: x | L22: x | M22: x | N22: x
D23: Mức 4 (<4) | E23: {=SUMPRODUCT((DREAMH!$D$2:$D$766="Về nhà")*(DREAMH!$B$2:$B$766="F3. Bảng hỏi sàng lọc sức khoẻ tâm thần (QST)")*(DREAMH!$C$2:$C$766>=2)*(DREAMH!$BC$2:$BC$766<4))} -> 0 | F23: {=SUMPRODUCT((DREAMH!$D$2:$D$766="Về nhà")*(DREAMH!$B$2:$B$766="F3. Bảng hỏi sàng lọc sức khoẻ tâm thần (QST)")*(DREAMH!$C$2:$C$766>=2)*(DREAMH!$BC$2:$BC$766<4)*(INDEX(DREAMH!$K$2:$K$766,MATCH(DREAMH!$A$2:$A$766,DREAMH!$A$2:$A$766,0))="Người sử dụng ma túy (PUD)"))} -> 0 | G23: {=SUMPRODUCT((DREAMH!$D$2:$D$766="Về nhà")*(DREAMH!$B$2:$B$766="F3. Bảng hỏi sàng lọc sức khoẻ tâm thần (QST)")*(DREAMH!$C$2:$C$766>=2)*(DREAMH!$BC$2:$BC$766<4)*(INDEX(DREAMH!$K$2:$K$766,MATCH(DREAMH!$A$2:$A$766,DREAMH!$A$2:$A$766,0))="Người sống chung với HIV (PLHIV)"))} -> 0 | H23: {=SUMPRODUCT((DREAMH!$D$2:$D$766="Về nhà")*(DREAMH!$B$2:$B$766="F3. Bảng hỏi sàng lọc sức khoẻ tâm thần (QST)")*(DREAMH!$C$2:$C$766>=2)*(DREAMH!$BC$2:$BC$766<4)*(INDEX(DREAMH!$K$2:$K$766,MATCH(DREAMH!$A$2:$A$766,DREAMH!$A$2:$A$766,0))="Người chuyển giới (TG)"))} -> 0 | I23: {=SUMPRODUCT((DREAMH!$D$2:$D$766="Về nhà")*(DREAMH!$B$2:$B$766="F3. Bảng hỏi sàng lọc sức khoẻ tâm thần (QST)")*(DREAMH!$C$2:$C$766>=2)*(DREAMH!$BC$2:$BC$766<4)*(INDEX(DREAMH!$K$2:$K$766,MATCH(DREAMH!$A$2:$A$766,DREAMH!$A$2:$A$766,0))="Người bán dâm (SW)"))} -> 0 | J23: {=SUMPRODUCT((DREAMH!$D$2:$D$766="Về nhà")*(DREAMH!$B$2:$B$766="F3. Bảng hỏi sàng lọc sức khoẻ tâm thần (QST)")*(DREAMH!$C$2:$C$766>=2)*(DREAMH!$BC$2:$BC$766<4)*(INDEX(DREAMH!$K$2:$K$766,MATCH(DREAMH!$A$2:$A$766,DREAMH!$A$2:$A$766,0))="Nam quan hệ tình dục đồng giới (MSM)"))} -> 0 | K23: x | L23: x | M23: x | N23: x
B24: 3 | C24: Số lượt KH được chuyển gửi khám SKTT | E24: {=SUMPRODUCT((DREAMH!$D$2:$D$766="Về nhà")*(DREAMH!$B$2:$B$766="F6. Thông tin chẩn đoán và điều trị"))} -> 12 | F24: {=SUMPRODUCT((DREAMH!$D$2:$D$766="Về nhà")*(DREAMH!$B$2:$B$766="F6. Thông tin chẩn đoán và điều trị")*(INDEX(DREAMH!$K$2:$K$766,MATCH(DREAMH!$A$2:$A$766,DREAMH!$A$2:$A$766,0))="Người sử dụng ma túy (PUD)"))} -> 8 | G24: {=SUMPRODUCT((DREAMH!$D$2:$D$766="Về nhà")*(DREAMH!$B$2:$B$766="F6. Thông tin chẩn đoán và điều trị")*(INDEX(DREAMH!$K$2:$K$766,MATCH(DREAMH!$A$2:$A$766,DREAMH!$A$2:$A$766,0))="Người sống chung với HIV (PLHIV)"))} -> 3 | H24: {=SUMPRODUCT((DREAMH!$D$2:$D$766="Về nhà")*(DREAMH!$B$2:$B$766="F6. Thông tin chẩn đoán và điều trị")*(INDEX(DREAMH!$K$2:$K$766,MATCH(DREAMH!$A$2:$A$766,DREAMH!$A$2:$A$766,0))="Người chuyển giới (TG)"))} -> 0 | I24: {=SUMPRODUCT((DREAMH!$D$2:$D$766="Về nhà")*(DREAMH!$B$2:$B$766="F6. Thông tin chẩn đoán và điều trị")*(INDEX(DREAMH!$K$2:$K$766,MATCH(DREAMH!$A$2:$A$766,DREAMH!$A$2:$A$766,0))="Người bán dâm (SW)"))} -> 1 | J24: {=SUMPRODUCT((DREAMH!$D$2:$D$766="Về nhà")*(DREAMH!$B$2:$B$766="F6. Thông tin chẩn đoán và điều trị")*(INDEX(DREAMH!$K$2:$K$766,MATCH(DREAMH!$A$2:$A$766,DREAMH!$A$2:$A$766,0))="Nam quan hệ tình dục đồng giới (MSM)"))} -> 0 | K24: x | L24: x | M24: x | N24: x | P24: Tổng số lượt trong tháng (dễ nhìn check báo cáo và thánh quyết toán)
B25: 4 | C25: Số KH được chuyển gửi khám SKTT, trong đó: | E25: {=SUMPRODUCT((DREAMH!$D$2:$D$766="Về nhà")*(DREAMH!$B$2:$B$766="F6. Thông tin chẩn đoán và điều trị") / (COUNTIFS(DREAMH!$A$2:$A$766, DREAMH!$A$2:$A$766, DREAMH!$B$2:$B$766, "F6. Thông tin chẩn đoán và điều trị") + (COUNTIFS(DREAMH!$A$2:$A$766, DREAMH!$A$2:$A$766, DREAMH!$B$2:$B$766, "F6. Thông tin chẩn đoán và điều trị")=0)))} -> 12 | F25: {=SUMPRODUCT((DREAMH!$D$2:$D$766="Về nhà")*(DREAMH!$B$2:$B$766="F6. Thông tin chẩn đoán và điều trị")*(INDEX(DREAMH!$K$2:$K$766,MATCH(DREAMH!$A$2:$A$766,DREAMH!$A$2:$A$766,0))="Người sử dụng ma túy (PUD)"))} -> 8 | G25: {=SUMPRODUCT((DREAMH!$D$2:$D$766="Về nhà")*(DREAMH!$B$2:$B$766="F6. Thông tin chẩn đoán và điều trị")*(INDEX(DREAMH!$K$2:$K$766,MATCH(DREAMH!$A$2:$A$766,DREAMH!$A$2:$A$766,0))="Người sống chung với HIV (PLHIV)"))} -> 3 | H25: {=SUMPRODUCT((DREAMH!$D$2:$D$766="Về nhà")*(DREAMH!$B$2:$B$766="F6. Thông tin chẩn đoán và điều trị")*(INDEX(DREAMH!$K$2:$K$766,MATCH(DREAMH!$A$2:$A$766,DREAMH!$A$2:$A$766,0))="Người chuyển giới (TG)"))} -> 0 | I25: {=SUMPRODUCT((DREAMH!$D$2:$D$766="Về nhà")*(DREAMH!$B$2:$B$766="F6. Thông tin chẩn đoán và điều trị")*(INDEX(DREAMH!$K$2:$K$766,MATCH(DREAMH!$A$2:$A$766,DREAMH!$A$2:$A$766,0))="Người bán dâm (SW)"))} -> 1 | J25: {=SUMPRODUCT((DREAMH!$D$2:$D$766="Về nhà")*(DREAMH!$B$2:$B$766="F6. Thông tin chẩn đoán và điều trị")*(INDEX(DREAMH!$K$2:$K$766,MATCH(DREAMH!$A$2:$A$766,DREAMH!$A$2:$A$766,0))="Nam quan hệ tình dục đồng giới (MSM)"))} -> 0 | K25: x | L25: x | M25: x | N25: x | O25: Dữ liệu từ biểu mẫu khám và điều trị SKTT
C26: Số KH được chuyển gửi khám SKTT lần 1 | E26: {=SUMPRODUCT((DREAMH!$D$2:$D$766="Về nhà")*(DREAMH!$B$2:$B$766="F6. Thông tin chẩn đoán và điều trị")*(DREAMH!$DA$2:$DA$766="Khám lần đầu"))} -> 12 | F26: {=SUMPRODUCT((DREAMH!$D$2:$D$766="Về nhà")*(DREAMH!$B$2:$B$766="F6. Thông tin chẩn đoán và điều trị")*(DREAMH!$DA$2:$DA$766="Khám lần đầu")*(INDEX(DREAMH!$K$2:$K$766,MATCH(DREAMH!$A$2:$A$766,DREAMH!$A$2:$A$766,0))="Người sử dụng ma túy (PUD)"))} -> 8 | G26: {=SUMPRODUCT((DREAMH!$D$2:$D$766="Về nhà")*(DREAMH!$B$2:$B$766="F6. Thông tin chẩn đoán và điều trị")*(DREAMH!$DA$2:$DA$766="Khám lần đầu")*(INDEX(DREAMH!$K$2:$K$766,MATCH(DREAMH!$A$2:$A$766,DREAMH!$A$2:$A$766,0))="Người sống chung với HIV (PLHIV)"))} -> 3 | H26: {=SUMPRODUCT((DREAMH!$D$2:$D$766="Về nhà")*(DREAMH!$B$2:$B$766="F6. Thông tin chẩn đoán và điều trị")*(DREAMH!$DA$2:$DA$766="Khám lần đầu")*(INDEX(DREAMH!$K$2:$K$766,MATCH(DREAMH!$A$2:$A$766,DREAMH!$A$2:$A$766,0))="Người chuyển giới (TG)"))} -> 0 | I26: {=SUMPRODUCT((DREAMH!$D$2:$D$766="Về nhà")*(DREAMH!$B$2:$B$766="F6. Thông tin chẩn đoán và điều trị")*(DREAMH!$DA$2:$DA$766="Khám lần đầu")*(INDEX(DREAMH!$K$2:$K$766,MATCH(DREAMH!$A$2:$A$766,DREAMH!$A$2:$A$766,0))="Người bán dâm (SW)"))} -> 1 | J26: {=SUMPRODUCT((DREAMH!$D$2:$D$766="Về nhà")*(DREAMH!$B$2:$B$766="F6. Thông tin chẩn đoán và điều trị")*(DREAMH!$DA$2:$DA$766="Khám lần đầu")*(INDEX(DREAMH!$K$2:$K$766,MATCH(DREAMH!$A$2:$A$766,DREAMH!$A$2:$A$766,0))="Nam quan hệ tình dục đồng giới (MSM)"))} -> 0 | K26: x | L26: x | M26: x | N26: x
C27: Số KH được tái khám SKTT | E27: {=SUMPRODUCT((DREAMH!$D$2:$D$766="Về nhà")*(DREAMH!$B$2:$B$766="F6. Thông tin chẩn đoán và điều trị")*(DREAMH!$DA$2:$DA$766="Tái khám"))} -> 0 | F27: {=SUMPRODUCT((DREAMH!$D$2:$D$766="Về nhà")*(DREAMH!$B$2:$B$766="F6. Thông tin chẩn đoán và điều trị")*(DREAMH!$DA$2:$DA$766="Tái khám")*(INDEX(DREAMH!$K$2:$K$766,MATCH(DREAMH!$A$2:$A$766,DREAMH!$A$2:$A$766,0))="Người sử dụng ma túy (PUD)"))} -> 0 | G27: {=SUMPRODUCT((DREAMH!$D$2:$D$766="Về nhà")*(DREAMH!$B$2:$B$766="F6. Thông tin chẩn đoán và điều trị")*(DREAMH!$DA$2:$DA$766="Tái khám")*(INDEX(DREAMH!$K$2:$K$766,MATCH(DREAMH!$A$2:$A$766,DREAMH!$A$2:$A$766,0))="Người sống chung với HIV (PLHIV)"))} -> 0 | H27: {=SUMPRODUCT((DREAMH!$D$2:$D$766="Về nhà")*(DREAMH!$B$2:$B$766="F6. Thông tin chẩn đoán và điều trị")*(DREAMH!$DA$2:$DA$766="Tái khám")*(INDEX(DREAMH!$K$2:$K$766,MATCH(DREAMH!$A$2:$A$766,DREAMH!$A$2:$A$766,0))="Người chuyển giới (TG)"))} -> 0 | I27: {=SUMPRODUCT((DREAMH!$D$2:$D$766="Về nhà")*(DREAMH!$B$2:$B$766="F6. Thông tin chẩn đoán và điều trị")*(DREAMH!$DA$2:$DA$766="Tái khám")*(INDEX(DREAMH!$K$2:$K$766,MATCH(DREAMH!$A$2:$A$766,DREAMH!$A$2:$A$766,0))="Người bán dâm (SW)"))} -> 0 | J27: {=SUMPRODUCT((DREAMH!$D$2:$D$766="Về nhà")*(DREAMH!$B$2:$B$766="F6. Thông tin chẩn đoán và điều trị")*(DREAMH!$DA$2:$DA$766="Tái khám")*(INDEX(DREAMH!$K$2:$K$766,MATCH(DREAMH!$A$2:$A$766,DREAMH!$A$2:$A$766,0))="Nam quan hệ tình dục đồng giới (MSM)"))} -> 0 | K27: x | L27: x | M27: x | N27: x
C28: Số lượt KH được tái khám SKTT | E28: {=SUMPRODUCT((DREAMH!$D$2:$D$766="Về nhà")*(DREAMH!$B$2:$B$766="F6. Thông tin chẩn đoán và điều trị")*(DREAMH!$DA$2:$DA$766="Tái khám"))} -> 0 | F28: {=SUMPRODUCT((DREAMH!$D$2:$D$766="Về nhà")*(DREAMH!$B$2:$B$766="F6. Thông tin chẩn đoán và điều trị")*(DREAMH!$DA$2:$DA$766="Tái khám")*(INDEX(DREAMH!$K$2:$K$766,MATCH(DREAMH!$A$2:$A$766,DREAMH!$A$2:$A$766,0))="Người sử dụng ma túy (PUD)"))} -> 0 | G28: {=SUMPRODUCT((DREAMH!$D$2:$D$766="Về nhà")*(DREAMH!$B$2:$B$766="F6. Thông tin chẩn đoán và điều trị")*(DREAMH!$DA$2:$DA$766="Tái khám")*(INDEX(DREAMH!$K$2:$K$766,MATCH(DREAMH!$A$2:$A$766,DREAMH!$A$2:$A$766,0))="Người sống chung với HIV (PLHIV)"))} -> 0 | H28: {=SUMPRODUCT((DREAMH!$D$2:$D$766="Về nhà")*(DREAMH!$B$2:$B$766="F6. Thông tin chẩn đoán và điều trị")*(DREAMH!$DA$2:$DA$766="Tái khám")*(INDEX(DREAMH!$K$2:$K$766,MATCH(DREAMH!$A$2:$A$766,DREAMH!$A$2:$A$766,0))="Người chuyển giới (TG)"))} -> 0 | I28: {=SUMPRODUCT((DREAMH!$D$2:$D$766="Về nhà")*(DREAMH!$B$2:$B$766="F6. Thông tin chẩn đoán và điều trị")*(DREAMH!$DA$2:$DA$766="Tái khám")*(INDEX(DREAMH!$K$2:$K$766,MATCH(DREAMH!$A$2:$A$766,DREAMH!$A$2:$A$766,0))="Người bán dâm (SW)"))} -> 0 | J28: {=SUMPRODUCT((DREAMH!$D$2:$D$766="Về nhà")*(DREAMH!$B$2:$B$766="F6. Thông tin chẩn đoán và điều trị")*(DREAMH!$DA$2:$DA$766="Tái khám")*(INDEX(DREAMH!$K$2:$K$766,MATCH(DREAMH!$A$2:$A$766,DREAMH!$A$2:$A$766,0))="Nam quan hệ tình dục đồng giới (MSM)"))} -> 0 | K28: x | L28: x | M28: x | N28: x
B29: 5 | C29: Số KH được điều trị nội trú (nhập viện) | E29: {=SUMPRODUCT((DREAMH!$D$2:$D$766="Về nhà")*(DREAMH!$B$2:$B$766="F6. Thông tin chẩn đoán và điều trị")*(DREAMH!$DL$2:$DL$766="Chọn"))} -> 1 | F29: {=SUMPRODUCT((DREAMH!$D$2:$D$766="Về nhà")*(DREAMH!$B$2:$B$766="F6. Thông tin chẩn đoán và điều trị")*(DREAMH!$DL$2:$DL$766="Chọn")*(INDEX(DREAMH!$K$2:$K$766,MATCH(DREAMH!$A$2:$A$766,DREAMH!$A$2:$A$766,0))="Người sử dụng ma túy (PUD)"))} -> 0 | G29: {=SUMPRODUCT((DREAMH!$D$2:$D$766="Về nhà")*(DREAMH!$B$2:$B$766="F6. Thông tin chẩn đoán và điều trị")*(DREAMH!$DL$2:$DL$766="Chọn")*(INDEX(DREAMH!$K$2:$K$766,MATCH(DREAMH!$A$2:$A$766,DREAMH!$A$2:$A$766,0))="Người sống chung với HIV (PLHIV)"))} -> 0 | H29: {=SUMPRODUCT((DREAMH!$D$2:$D$766="Về nhà")*(DREAMH!$B$2:$B$766="F6. Thông tin chẩn đoán và điều trị")*(DREAMH!$DL$2:$DL$766="Chọn")*(INDEX(DREAMH!$K$2:$K$766,MATCH(DREAMH!$A$2:$A$766,DREAMH!$A$2:$A$766,0))="Người chuyển giới (TG)"))} -> 0 | I29: {=SUMPRODUCT((DREAMH!$D$2:$D$766="Về nhà")*(DREAMH!$B$2:$B$766="F6. Thông tin chẩn đoán và điều trị")*(DREAMH!$DL$2:$DL$766="Chọn")*(INDEX(DREAMH!$K$2:$K$766,MATCH(DREAMH!$A$2:$A$766,DREAMH!$A$2:$A$766,0))="Người bán dâm (SW)"))} -> 1 | J29: {=SUMPRODUCT((DREAMH!$D$2:$D$766="Về nhà")*(DREAMH!$B$2:$B$766="F6. Thông tin chẩn đoán và điều trị")*(DREAMH!$DL$2:$DL$766="Chọn")*(INDEX(DREAMH!$K$2:$K$766,MATCH(DREAMH!$A$2:$A$766,DREAMH!$A$2:$A$766,0))="Nam quan hệ tình dục đồng giới (MSM)"))} -> 0 | K29: x | L29: x | M29: x | N29: x
B30: 6 | C30: Số KH được hỗ trợ mua thẻ Bảo hiểm y tế | E30: {=SUMPRODUCT((DREAMH!$D$2:$D$766="Về nhà")*(DREAMH!$B$2:$B$766="F5. Phiếu hỗ trợ tuân thủ điều trị")*(DREAMH!$BG$2:$BG$766="Chọn"))} -> 0 | F30: {=SUMPRODUCT((DREAMH!$D$2:$D$766="Về nhà")*(DREAMH!$B$2:$B$766="F5. Phiếu hỗ trợ tuân thủ điều trị")*(DREAMH!$BG$2:$BG$766="Chọn")*(INDEX(DREAMH!$K$2:$K$766,MATCH(DREAMH!$A$2:$A$766,DREAMH!$A$2:$A$766,0))="Người sử dụng ma túy (PUD)"))} -> 0 | G30: {=SUMPRODUCT((DREAMH!$D$2:$D$766="Về nhà")*(DREAMH!$B$2:$B$766="F5. Phiếu hỗ trợ tuân thủ điều trị")*(DREAMH!$BG$2:$BG$766="Chọn")*(INDEX(DREAMH!$K$2:$K$766,MATCH(DREAMH!$A$2:$A$766,DREAMH!$A$2:$A$766,0))="Người sống chung với HIV (PLHIV)"))} -> 0 | H30: {=SUMPRODUCT((DREAMH!$D$2:$D$766="Về nhà")*(DREAMH!$B$2:$B$766="F5. Phiếu hỗ trợ tuân thủ điều trị")*(DREAMH!$BG$2:$BG$766="Chọn")*(INDEX(DREAMH!$K$2:$K$766,MATCH(DREAMH!$A$2:$A$766,DREAMH!$A$2:$A$766,0))="Người chuyển giới (TG)"))} -> 0 | I30: {=SUMPRODUCT((DREAMH!$D$2:$D$766="Về nhà")*(DREAMH!$B$2:$B$766="F5. Phiếu hỗ trợ tuân thủ điều trị")*(DREAMH!$BG$2:$BG$766="Chọn")*(INDEX(DREAMH!$K$2:$K$766,MATCH(DREAMH!$A$2:$A$766,DREAMH!$A$2:$A$766,0))="Người bán dâm (SW)"))} -> 0 | J30: {=SUMPRODUCT((DREAMH!$D$2:$D$766="Về nhà")*(DREAMH!$B$2:$B$766="F5. Phiếu hỗ trợ tuân thủ điều trị")*(DREAMH!$BG$2:$BG$766="Chọn")*(INDEX(DREAMH!$K$2:$K$766,MATCH(DREAMH!$A$2:$A$766,DREAMH!$A$2:$A$766,0))="Nam quan hệ tình dục đồng giới (MSM)"))} -> 0 | K30: x | L30: x | M30: x | N30: x | O30: Chưa có biểu mẫu nhập thông tin này Bổ sung
B31: IV | C31: CÁC CAN THIỆP CÁ NHÂN VÀ CAN THIỆP NHÓM | O31: Dữ liệu từ biểu mẫu tư vấn
B32: 1 | C32: Số lượt KH được tư vấn cá nhân | E32: {=SUMPRODUCT((DREAMH!$D$2:$D$766="Về nhà")*((DREAMH!$B$2:$B$766="F7. Phiếu tư vấn lần 1")+(DREAMH!$B$2:$B$766="F8. Phiếu tư vấn (từ lần 2)")))} -> 0 | F32: {=SUMPRODUCT((DREAMH!$D$2:$D$766="Về nhà")*((DREAMH!$B$2:$B$766="F7. Phiếu tư vấn lần 1")+(DREAMH!$B$2:$B$766="F8. Phiếu tư vấn (từ lần 2)"))*(INDEX(DREAMH!$K$2:$K$766,MATCH(DREAMH!$A$2:$A$766,DREAMH!$A$2:$A$766,0))="Người sử dụng ma túy (PUD)"))} -> 0 | G32: {=SUMPRODUCT((DREAMH!$D$2:$D$766="Về nhà")*((DREAMH!$B$2:$B$766="F7. Phiếu tư vấn lần 1")+(DREAMH!$B$2:$B$766="F8. Phiếu tư vấn (từ lần 2)"))*(INDEX(DREAMH!$K$2:$K$766,MATCH(DREAMH!$A$2:$A$766,DREAMH!$A$2:$A$766,0))="Người sống chung với HIV (PLHIV)"))} -> 0 | H32: {=SUMPRODUCT((DREAMH!$D$2:$D$766="Về nhà")*((DREAMH!$B$2:$B$766="F7. Phiếu tư vấn lần 1")+(DREAMH!$B$2:$B$766="F8. Phiếu tư vấn (từ lần 2)"))*(INDEX(DREAMH!$K$2:$K$766,MATCH(DREAMH!$A$2:$A$766,DREAMH!$A$2:$A$766,0))="Người chuyển giới (TG)"))} -> 0 | I32: {=SUMPRODUCT((DREAMH!$D$2:$D$766="Về nhà")*((DREAMH!$B$2:$B$766="F7. Phiếu tư vấn lần 1")+(DREAMH!$B$2:$B$766="F8. Phiếu tư vấn (từ lần 2)"))*(INDEX(DREAMH!$K$2:$K$766,MATCH(DREAMH!$A$2:$A$766,DREAMH!$A$2:$A$766,0))="Người bán dâm (SW)"))} -> 0 | J32: {=SUMPRODUCT((DREAMH!$D$2:$D$766="Về nhà")*((DREAMH!$B$2:$B$766="F7. Phiếu tư vấn lần 1")+(DREAMH!$B$2:$B$766="F8. Phiếu tư vấn (từ lần 2)"))*(INDEX(DREAMH!$K$2:$K$766,MATCH(DREAMH!$A$2:$A$766,DREAMH!$A$2:$A$766,0))="Nam quan hệ tình dục đồng giới (MSM)"))} -> 0 | K32: x | L32: x | M32: x | N32: x
B33: 2 | C33: Số KH được tư vấn cá nhân, trong đó: | E33: {=SUMPRODUCT((DREAMH!$D$2:$D$766="Về nhà")*(DREAMH!$B$2:$B$766="F7. Phiếu tư vấn lần 1"))} -> 0 | F33: {=SUMPRODUCT((DREAMH!$D$2:$D$766="Về nhà")*(DREAMH!$B$2:$B$766="F7. Phiếu tư vấn lần 1")*(INDEX(DREAMH!$K$2:$K$766,MATCH(DREAMH!$A$2:$A$766,DREAMH!$A$2:$A$766,0))="Người sử dụng ma túy (PUD)"))} -> 0 | G33: {=SUMPRODUCT((DREAMH!$D$2:$D$766="Về nhà")*(DREAMH!$B$2:$B$766="F7. Phiếu tư vấn lần 1")*(INDEX(DREAMH!$K$2:$K$766,MATCH(DREAMH!$A$2:$A$766,DREAMH!$A$2:$A$766,0))="Người sống chung với HIV (PLHIV)"))} -> 0 | H33: {=SUMPRODUCT((DREAMH!$D$2:$D$766="Về nhà")*(DREAMH!$B$2:$B$766="F7. Phiếu tư vấn lần 1")*(INDEX(DREAMH!$K$2:$K$766,MATCH(DREAMH!$A$2:$A$766,DREAMH!$A$2:$A$766,0))="Người chuyển giới (TG)"))} -> 0 | I33: {=SUMPRODUCT((DREAMH!$D$2:$D$766="Về nhà")*(DREAMH!$B$2:$B$766="F7. Phiếu tư vấn lần 1")*(INDEX(DREAMH!$K$2:$K$766,MATCH(DREAMH!$A$2:$A$766,DREAMH!$A$2:$A$766,0))="Người bán dâm (SW)"))} -> 0 | J33: {=SUMPRODUCT((DREAMH!$D$2:$D$766="Về nhà")*(DREAMH!$B$2:$B$766="F7. Phiếu tư vấn lần 1")*(INDEX(DREAMH!$K$2:$K$766,MATCH(DREAMH!$A$2:$A$766,DREAMH!$A$2:$A$766,0))="Nam quan hệ tình dục đồng giới (MSM)"))} -> 0 | K33: x | L33: x | M33: x | N33: x
C34: Số KH được tư vấn 1 lần | E34: {=SUMPRODUCT((DREAMH!$D$2:$D$766="Về nhà")*(DREAMH!$B$2:$B$766="F7. Phiếu tư vấn lần 1")*(COUNTIFS(DREAMH!$A$2:$A$766, DREAMH!$A$2:$A$766, DREAMH!$B$2:$B$766, "F8. Phiếu tư vấn (từ lần 2)")=0))} -> 0 | F34: {=SUMPRODUCT((DREAMH!$D$2:$D$766="Về nhà")*(DREAMH!$B$2:$B$766="F7. Phiếu tư vấn lần 1")*(COUNTIFS(DREAMH!$A$2:$A$766, DREAMH!$A$2:$A$766, DREAMH!$B$2:$B$766, "F8. Phiếu tư vấn (từ lần 2)")=0)*(INDEX(DREAMH!$K$2:$K$766,MATCH(DREAMH!$A$2:$A$766,DREAMH!$A$2:$A$766,0))="Người sử dụng ma túy (PUD)"))} -> 0 | G34: {=SUMPRODUCT((DREAMH!$D$2:$D$766="Về nhà")*(DREAMH!$B$2:$B$766="F7. Phiếu tư vấn lần 1")*(COUNTIFS(DREAMH!$A$2:$A$766, DREAMH!$A$2:$A$766, DREAMH!$B$2:$B$766, "F8. Phiếu tư vấn (từ lần 2)")=0)*(INDEX(DREAMH!$K$2:$K$766,MATCH(DREAMH!$A$2:$A$766,DREAMH!$A$2:$A$766,0))="Người sống chung với HIV (PLHIV)"))} -> 0 | H34: {=SUMPRODUCT((DREAMH!$D$2:$D$766="Về nhà")*(DREAMH!$B$2:$B$766="F7. Phiếu tư vấn lần 1")*(COUNTIFS(DREAMH!$A$2:$A$766, DREAMH!$A$2:$A$766, DREAMH!$B$2:$B$766, "F8. Phiếu tư vấn (từ lần 2)")=0)*(INDEX(DREAMH!$K$2:$K$766,MATCH(DREAMH!$A$2:$A$766,DREAMH!$A$2:$A$766,0))="Người chuyển giới (TG)"))} -> 0 | I34: {=SUMPRODUCT((DREAMH!$D$2:$D$766="Về nhà")*(DREAMH!$B$2:$B$766="F7. Phiếu tư vấn lần 1")*(COUNTIFS(DREAMH!$A$2:$A$766, DREAMH!$A$2:$A$766, DREAMH!$B$2:$B$766, "F8. Phiếu tư vấn (từ lần 2)")=0)*(INDEX(DREAMH!$K$2:$K$766,MATCH(DREAMH!$A$2:$A$766,DREAMH!$A$2:$A$766,0))="Người bán dâm (SW)"))} -> 0 | J34: {=SUMPRODUCT((DREAMH!$D$2:$D$766="Về nhà")*(DREAMH!$B$2:$B$766="F7. Phiếu tư vấn lần 1")*(COUNTIFS(DREAMH!$A$2:$A$766, DREAMH!$A$2:$A$766, DREAMH!$B$2:$B$766, "F8. Phiếu tư vấn (từ lần 2)")=0)*(INDEX(DREAMH!$K$2:$K$766,MATCH(DREAMH!$A$2:$A$766,DREAMH!$A$2:$A$766,0))="Nam quan hệ tình dục đồng giới (MSM)"))} -> 0 | L34: x | M34: x | N34: x
C35: Số KH được tư vấn 2 lần | E35: {=SUMPRODUCT((DREAMH!$D$2:$D$766="Về nhà")*(DREAMH!$B$2:$B$766="F8. Phiếu tư vấn (từ lần 2)")*(COUNTIFS(DREAMH!$A$2:$A$766, DREAMH!$A$2:$A$766, DREAMH!$B$2:$B$766, "F8. Phiếu tư vấn (từ lần 2)")=1))} -> 0 | F35: {=SUMPRODUCT((DREAMH!$D$2:$D$766="Về nhà")*(DREAMH!$B$2:$B$766="F8. Phiếu tư vấn (từ lần 2)")*(COUNTIFS(DREAMH!$A$2:$A$766, DREAMH!$A$2:$A$766, DREAMH!$B$2:$B$766, "F8. Phiếu tư vấn (từ lần 2)")=1)*(INDEX(DREAMH!$K$2:$K$766,MATCH(DREAMH!$A$2:$A$766,DREAMH!$A$2:$A$766,0))="Người sử dụng ma túy (PUD)"))} -> 0 | G35: {=SUMPRODUCT((DREAMH!$D$2:$D$766="Về nhà")*(DREAMH!$B$2:$B$766="F8. Phiếu tư vấn (từ lần 2)")*(COUNTIFS(DREAMH!$A$2:$A$766, DREAMH!$A$2:$A$766, DREAMH!$B$2:$B$766, "F8. Phiếu tư vấn (từ lần 2)")=1)*(INDEX(DREAMH!$K$2:$K$766,MATCH(DREAMH!$A$2:$A$766,DREAMH!$A$2:$A$766,0))="Người sống chung với HIV (PLHIV)"))} -> 0 | H35: {=SUMPRODUCT((DREAMH!$D$2:$D$766="Về nhà")*(DREAMH!$B$2:$B$766="F8. Phiếu tư vấn (từ lần 2)")*(COUNTIFS(DREAMH!$A$2:$A$766, DREAMH!$A$2:$A$766, DREAMH!$B$2:$B$766, "F8. Phiếu tư vấn (từ lần 2)")=1)*(INDEX(DREAMH!$K$2:$K$766,MATCH(DREAMH!$A$2:$A$766,DREAMH!$A$2:$A$766,0))="Người chuyển giới (TG)"))} -> 0 | I35: {=SUMPRODUCT((DREAMH!$D$2:$D$766="Về nhà")*(DREAMH!$B$2:$B$766="F8. Phiếu tư vấn (từ lần 2)")*(COUNTIFS(DREAMH!$A$2:$A$766, DREAMH!$A$2:$A$766, DREAMH!$B$2:$B$766, "F8. Phiếu tư vấn (từ lần 2)")=1)*(INDEX(DREAMH!$K$2:$K$766,MATCH(DREAMH!$A$2:$A$766,DREAMH!$A$2:$A$766,0))="Người bán dâm (SW)"))} -> 0 | J35: {=SUMPRODUCT((DREAMH!$D$2:$D$766="Về nhà")*(DREAMH!$B$2:$B$766="F8. Phiếu tư vấn (từ lần 2)")*(COUNTIFS(DREAMH!$A$2:$A$766, DREAMH!$A$2:$A$766, DREAMH!$B$2:$B$766, "F8. Phiếu tư vấn (từ lần 2)")=1)*(INDEX(DREAMH!$K$2:$K$766,MATCH(DREAMH!$A$2:$A$766,DREAMH!$A$2:$A$766,0))="Nam quan hệ tình dục đồng giới (MSM)"))} -> 0 | L35: x | M35: x | N35: x
C36: Số KH được tư vấn từ 3 lần trở lên | E36: {=SUMPRODUCT((DREAMH!$D$2:$D$766="Về nhà")*(DREAMH!$B$2:$B$766="F8. Phiếu tư vấn (từ lần 2)")*(COUNTIFS(DREAMH!$A$2:$A$766, DREAMH!$A$2:$A$766, DREAMH!$B$2:$B$766, "F8. Phiếu tư vấn (từ lần 2)")>=2) / (COUNTIFS(DREAMH!$A$2:$A$766, DREAMH!$A$2:$A$766, DREAMH!$B$2:$B$766, "F8. Phiếu tư vấn (từ lần 2)") + (COUNTIFS(DREAMH!$A$2:$A$766, DREAMH!$A$2:$A$766, DREAMH!$B$2:$B$766, "F8. Phiếu tư vấn (từ lần 2)")=0)))} -> 0 | F36: {=SUMPRODUCT((DREAMH!$D$2:$D$766="Về nhà")*(DREAMH!$B$2:$B$766="F8. Phiếu tư vấn (từ lần 2)")*(COUNTIFS(DREAMH!$A$2:$A$766, DREAMH!$A$2:$A$766, DREAMH!$B$2:$B$766, "F8. Phiếu tư vấn (từ lần 2)")>=2)*(INDEX(DREAMH!$K$2:$K$766,MATCH(DREAMH!$A$2:$A$766,DREAMH!$A$2:$A$766,0))="Người sử dụng ma túy (PUD)") / (COUNTIFS(DREAMH!$A$2:$A$766, DREAMH!$A$2:$A$766, DREAMH!$B$2:$B$766, "F8. Phiếu tư vấn (từ lần 2)") + (COUNTIFS(DREAMH!$A$2:$A$766, DREAMH!$A$2:$A$766, DREAMH!$B$2:$B$766, "F8. Phiếu tư vấn (từ lần 2)")=0)))} -> 0 | G36: {=SUMPRODUCT((DREAMH!$D$2:$D$766="Về nhà")*(DREAMH!$B$2:$B$766="F8. Phiếu tư vấn (từ lần 2)")*(COUNTIFS(DREAMH!$A$2:$A$766, DREAMH!$A$2:$A$766, DREAMH!$B$2:$B$766, "F8. Phiếu tư vấn (từ lần 2)")>=2)*(INDEX(DREAMH!$K$2:$K$766,MATCH(DREAMH!$A$2:$A$766,DREAMH!$A$2:$A$766,0))="Người sống chung với HIV (PLHIV)") / (COUNTIFS(DREAMH!$A$2:$A$766, DREAMH!$A$2:$A$766, DREAMH!$B$2:$B$766, "F8. Phiếu tư vấn (từ lần 2)") + (COUNTIFS(DREAMH!$A$2:$A$766, DREAMH!$A$2:$A$766, DREAMH!$B$2:$B$766, "F8. Phiếu tư vấn (từ lần 2)")=0)))} -> 0 | H36: {=SUMPRODUCT((DREAMH!$D$2:$D$766="Về nhà")*(DREAMH!$B$2:$B$766="F8. Phiếu tư vấn (từ lần 2)")*(COUNTIFS(DREAMH!$A$2:$A$766, DREAMH!$A$2:$A$766, DREAMH!$B$2:$B$766, "F8. Phiếu tư vấn (từ lần 2)")>=2)*(INDEX(DREAMH!$K$2:$K$766,MATCH(DREAMH!$A$2:$A$766,DREAMH!$A$2:$A$766,0))="Người chuyển giới (TG)") / (COUNTIFS(DREAMH!$A$2:$A$766, DREAMH!$A$2:$A$766, DREAMH!$B$2:$B$766, "F8. Phiếu tư vấn (từ lần 2)") + (COUNTIFS(DREAMH!$A$2:$A$766, DREAMH!$A$2:$A$766, DREAMH!$B$2:$B$766, "F8. Phiếu tư vấn (từ lần 2)")=0)))} -> 0 | I36: {=SUMPRODUCT((DREAMH!$D$2:$D$766="Về nhà")*(DREAMH!$B$2:$B$766="F8. Phiếu tư vấn (từ lần 2)")*(COUNTIFS(DREAMH!$A$2:$A$766, DREAMH!$A$2:$A$766, DREAMH!$B$2:$B$766, "F8. Phiếu tư vấn (từ lần 2)")>=2)*(INDEX(DREAMH!$K$2:$K$766,MATCH(DREAMH!$A$2:$A$766,DREAMH!$A$2:$A$766,0))="Người bán dâm (SW)") / (COUNTIFS(DREAMH!$A$2:$A$766, DREAMH!$A$2:$A$766, DREAMH!$B$2:$B$766, "F8. Phiếu tư vấn (từ lần 2)") + (COUNTIFS(DREAMH!$A$2:$A$766, DREAMH!$A$2:$A$766, DREAMH!$B$2:$B$766, "F8. Phiếu tư vấn (từ lần 2)")=0)))} -> 0 | J36: {=SUMPRODUCT((DREAMH!$D$2:$D$766="Về nhà")*(DREAMH!$B$2:$B$766="F8. Phiếu tư vấn (từ lần 2)")*(COUNTIFS(DREAMH!$A$2:$A$766, DREAMH!$A$2:$A$766, DREAMH!$B$2:$B$766, "F8. Phiếu tư vấn (từ lần 2)")>=2)*(INDEX(DREAMH!$K$2:$K$766,MATCH(DREAMH!$A$2:$A$766,DREAMH!$A$2:$A$766,0))="Nam quan hệ tình dục đồng giới (MSM)") / (COUNTIFS(DREAMH!$A$2:$A$766, DREAMH!$A$2:$A$766, DREAMH!$B$2:$B$766, "F8. Phiếu tư vấn (từ lần 2)") + (COUNTIFS(DREAMH!$A$2:$A$766, DREAMH!$A$2:$A$766, DREAMH!$B$2:$B$766, "F8. Phiếu tư vấn (từ lần 2)")=0)))} -> 0 | L36: x | M36: x | N36: x
B37: 3 | C37: Số lượt KH được tham gia sinh hoạt nhóm | E37: {=SUMPRODUCT((DREAMH!$D$2:$D$766="Về nhà")*(DREAMH!$B$2:$B$766="F2. Truyền thông, sinh hoạt nhóm, vòng tròn chia sẻ, trị liệu nghệ thuật")*(DREAMH!$AA$2:$AA$766="Sinh hoạt nhóm"))} -> 0 | F37: {=SUMPRODUCT((DREAMH!$D$2:$D$766="Về nhà")*(DREAMH!$B$2:$B$766="F2. Truyền thông, sinh hoạt nhóm, vòng tròn chia sẻ, trị liệu nghệ thuật")*(DREAMH!$AA$2:$AA$766="Sinh hoạt nhóm")*(INDEX(DREAMH!$K$2:$K$766,MATCH(DREAMH!$A$2:$A$766,DREAMH!$A$2:$A$766,0))="Người sử dụng ma túy (PUD)"))} -> 0 | G37: {=SUMPRODUCT((DREAMH!$D$2:$D$766="Về nhà")*(DREAMH!$B$2:$B$766="F2. Truyền thông, sinh hoạt nhóm, vòng tròn chia sẻ, trị liệu nghệ thuật")*(DREAMH!$AA$2:$AA$766="Sinh hoạt nhóm")*(INDEX(DREAMH!$K$2:$K$766,MATCH(DREAMH!$A$2:$A$766,DREAMH!$A$2:$A$766,0))="Người sống chung với HIV (PLHIV)"))} -> 0 | H37: {=SUMPRODUCT((DREAMH!$D$2:$D$766="Về nhà")*(DREAMH!$B$2:$B$766="F2. Truyền thông, sinh hoạt nhóm, vòng tròn chia sẻ, trị liệu nghệ thuật")*(DREAMH!$AA$2:$AA$766="Sinh hoạt nhóm")*(INDEX(DREAMH!$K$2:$K$766,MATCH(DREAMH!$A$2:$A$766,DREAMH!$A$2:$A$766,0))="Người chuyển giới (TG)"))} -> 0 | I37: {=SUMPRODUCT((DREAMH!$D$2:$D$766="Về nhà")*(DREAMH!$B$2:$B$766="F2. Truyền thông, sinh hoạt nhóm, vòng tròn chia sẻ, trị liệu nghệ thuật")*(DREAMH!$AA$2:$AA$766="Sinh hoạt nhóm")*(INDEX(DREAMH!$K$2:$K$766,MATCH(DREAMH!$A$2:$A$766,DREAMH!$A$2:$A$766,0))="Người bán dâm (SW)"))} -> 0 | J37: {=SUMPRODUCT((DREAMH!$D$2:$D$766="Về nhà")*(DREAMH!$B$2:$B$766="F2. Truyền thông, sinh hoạt nhóm, vòng tròn chia sẻ, trị liệu nghệ thuật")*(DREAMH!$AA$2:$AA$766="Sinh hoạt nhóm")*(INDEX(DREAMH!$K$2:$K$766,MATCH(DREAMH!$A$2:$A$766,DREAMH!$A$2:$A$766,0))="Nam quan hệ tình dục đồng giới (MSM)"))} -> 0 | K37: x | L37: x | M37: x | N37: x | O37: Dữ liệu từ biểu mẫu sinh hoạt nhóm và can thiệp chữa lành | P37: Tổng số lượt trong tháng (dễ nhìn check báo cáo và thánh quyết toán)
B38: 4 | C38: Số KH được tham gia sinh hoạt nhóm | E38: {=SUMPRODUCT(((DREAMH!$D$2:$D$766="Về nhà")*(DREAMH!$B$2:$B$766="F2. Truyền thông, sinh hoạt nhóm, vòng tròn chia sẻ, trị liệu nghệ thuật")*(DREAMH!$AA$2:$AA$766="Sinh hoạt nhóm"))/(COUNTIFS(DREAMH!$A$2:$A$766,DREAMH!$A$2:$A$766,DREAMH!$B$2:$B$766,"F2. Truyền thông, sinh hoạt nhóm, vòng tròn chia sẻ, trị liệu nghệ thuật",DREAMH!$AA$2:$AA$766,"Sinh hoạt nhóm")+(COUNTIFS(DREAMH!$A$2:$A$766,DREAMH!$A$2:$A$766,DREAMH!$B$2:$B$766,"F2. Truyền thông, sinh hoạt nhóm, vòng tròn chia sẻ, trị liệu nghệ thuật",DREAMH!$AA$2:$AA$766,"Sinh hoạt nhóm")=0)))} -> 0 | F38: {=SUMPRODUCT(((DREAMH!$D$2:$D$766="Về nhà")*(DREAMH!$B$2:$B$766="F2. Truyền thông, sinh hoạt nhóm, vòng tròn chia sẻ, trị liệu nghệ thuật")*(DREAMH!$AA$2:$AA$766="Sinh hoạt nhóm"))*(INDEX(DREAMH!$K$2:$K$766,MATCH(DREAMH!$A$2:$A$766,DREAMH!$A$2:$A$766,0))="Người sử dụng ma túy (PUD)")/(COUNTIFS(DREAMH!$A$2:$A$766,DREAMH!$A$2:$A$766,DREAMH!$B$2:$B$766,"F2. Truyền thông, sinh hoạt nhóm, vòng tròn chia sẻ, trị liệu nghệ thuật",DREAMH!$AA$2:$AA$766,"Sinh hoạt nhóm")+(COUNTIFS(DREAMH!$A$2:$A$766,DREAMH!$A$2:$A$766,DREAMH!$B$2:$B$766,"F2. Truyền thông, sinh hoạt nhóm, vòng tròn chia sẻ, trị liệu nghệ thuật",DREAMH!$AA$2:$AA$766,"Sinh hoạt nhóm")=0)))} -> 0 | G38: {=SUMPRODUCT(((DREAMH!$D$2:$D$766="Về nhà")*(DREAMH!$B$2:$B$766="F2. Truyền thông, sinh hoạt nhóm, vòng tròn chia sẻ, trị liệu nghệ thuật")*(DREAMH!$AA$2:$AA$766="Sinh hoạt nhóm"))*(INDEX(DREAMH!$K$2:$K$766,MATCH(DREAMH!$A$2:$A$766,DREAMH!$A$2:$A$766,0))="Người sống chung với HIV (PLHIV)")/(COUNTIFS(DREAMH!$A$2:$A$766,DREAMH!$A$2:$A$766,DREAMH!$B$2:$B$766,"F2. Truyền thông, sinh hoạt nhóm, vòng tròn chia sẻ, trị liệu nghệ thuật",DREAMH!$AA$2:$AA$766,"Sinh hoạt nhóm")+(COUNTIFS(DREAMH!$A$2:$A$766,DREAMH!$A$2:$A$766,DREAMH!$B$2:$B$766,"F2. Truyền thông, sinh hoạt nhóm, vòng tròn chia sẻ, trị liệu nghệ thuật",DREAMH!$AA$2:$AA$766,"Sinh hoạt nhóm")=0)))} -> 0 | H38: {=SUMPRODUCT(((DREAMH!$D$2:$D$766="Về nhà")*(DREAMH!$B$2:$B$766="F2. Truyền thông, sinh hoạt nhóm, vòng tròn chia sẻ, trị liệu nghệ thuật")*(DREAMH!$AA$2:$AA$766="Sinh hoạt nhóm"))*(INDEX(DREAMH!$K$2:$K$766,MATCH(DREAMH!$A$2:$A$766,DREAMH!$A$2:$A$766,0))="Người chuyển giới (TG)")/(COUNTIFS(DREAMH!$A$2:$A$766,DREAMH!$A$2:$A$766,DREAMH!$B$2:$B$766,"F2. Truyền thông, sinh hoạt nhóm, vòng tròn chia sẻ, trị liệu nghệ thuật",DREAMH!$AA$2:$AA$766,"Sinh hoạt nhóm")+(COUNTIFS(DREAMH!$A$2:$A$766,DREAMH!$A$2:$A$766,DREAMH!$B$2:$B$766,"F2. Truyền thông, sinh hoạt nhóm, vòng tròn chia sẻ, trị liệu nghệ thuật",DREAMH!$AA$2:$AA$766,"Sinh hoạt nhóm")=0)))} -> 0 | I38: {=SUMPRODUCT(((DREAMH!$D$2:$D$766="Về nhà")*(DREAMH!$B$2:$B$766="F2. Truyền thông, sinh hoạt nhóm, vòng tròn chia sẻ, trị liệu nghệ thuật")*(DREAMH!$AA$2:$AA$766="Sinh hoạt nhóm"))*(INDEX(DREAMH!$K$2:$K$766,MATCH(DREAMH!$A$2:$A$766,DREAMH!$A$2:$A$766,0))="Người bán dâm (SW)")/(COUNTIFS(DREAMH!$A$2:$A$766,DREAMH!$A$2:$A$766,DREAMH!$B$2:$B$766,"F2. Truyền thông, sinh hoạt nhóm, vòng tròn chia sẻ, trị liệu nghệ thuật",DREAMH!$AA$2:$AA$766,"Sinh hoạt nhóm")+(COUNTIFS(DREAMH!$A$2:$A$766,DREAMH!$A$2:$A$766,DREAMH!$B$2:$B$766,"F2. Truyền thông, sinh hoạt nhóm, vòng tròn chia sẻ, trị liệu nghệ thuật",DREAMH!$AA$2:$AA$766,"Sinh hoạt nhóm")=0)))} -> 0 | J38: {=SUMPRODUCT(((DREAMH!$D$2:$D$766="Về nhà")*(DREAMH!$B$2:$B$766="F2. Truyền thông, sinh hoạt nhóm, vòng tròn chia sẻ, trị liệu nghệ thuật")*(DREAMH!$AA$2:$AA$766="Sinh hoạt nhóm"))*(INDEX(DREAMH!$K$2:$K$766,MATCH(DREAMH!$A$2:$A$766,DREAMH!$A$2:$A$766,0))="Nam quan hệ tình dục đồng giới (MSM)")/(COUNTIFS(DREAMH!$A$2:$A$766,DREAMH!$A$2:$A$766,DREAMH!$B$2:$B$766,"F2. Truyền thông, sinh hoạt nhóm, vòng tròn chia sẻ, trị liệu nghệ thuật",DREAMH!$AA$2:$AA$766,"Sinh hoạt nhóm")+(COUNTIFS(DREAMH!$A$2:$A$766,DREAMH!$A$2:$A$766,DREAMH!$B$2:$B$766,"F2. Truyền thông, sinh hoạt nhóm, vòng tròn chia sẻ, trị liệu nghệ thuật",DREAMH!$AA$2:$AA$766,"Sinh hoạt nhóm")=0)))} -> 0 | K38: x | L38: x | M38: x | N38: x
B39: 5 | C39: Số lượt KH được tham gia can thiệp chữa lành | E39: {=SUMPRODUCT((DREAMH!$D$2:$D$766="Về nhà")*(DREAMH!$B$2:$B$766="F2. Truyền thông, sinh hoạt nhóm, vòng tròn chia sẻ, trị liệu nghệ thuật")*(DREAMH!$AA$2:$AA$766="Can thiệp chữa lành"))} -> 0 | F39: {=SUMPRODUCT((DREAMH!$D$2:$D$766="Về nhà")*(DREAMH!$B$2:$B$766="F2. Truyền thông, sinh hoạt nhóm, vòng tròn chia sẻ, trị liệu nghệ thuật")*(DREAMH!$AA$2:$AA$766="Can thiệp chữa lành")*(INDEX(DREAMH!$K$2:$K$766,MATCH(DREAMH!$A$2:$A$766,DREAMH!$A$2:$A$766,0))="Người sử dụng ma túy (PUD)"))} -> 0 | G39: {=SUMPRODUCT((DREAMH!$D$2:$D$766="Về nhà")*(DREAMH!$B$2:$B$766="F2. Truyền thông, sinh hoạt nhóm, vòng tròn chia sẻ, trị liệu nghệ thuật")*(DREAMH!$AA$2:$AA$766="Can thiệp chữa lành")*(INDEX(DREAMH!$K$2:$K$766,MATCH(DREAMH!$A$2:$A$766,DREAMH!$A$2:$A$766,0))="Người sống chung với HIV (PLHIV)"))} -> 0 | H39: {=SUMPRODUCT((DREAMH!$D$2:$D$766="Về nhà")*(DREAMH!$B$2:$B$766="F2. Truyền thông, sinh hoạt nhóm, vòng tròn chia sẻ, trị liệu nghệ thuật")*(DREAMH!$AA$2:$AA$766="Can thiệp chữa lành")*(INDEX(DREAMH!$K$2:$K$766,MATCH(DREAMH!$A$2:$A$766,DREAMH!$A$2:$A$766,0))="Người chuyển giới (TG)"))} -> 0 | I39: {=SUMPRODUCT((DREAMH!$D$2:$D$766="Về nhà")*(DREAMH!$B$2:$B$766="F2. Truyền thông, sinh hoạt nhóm, vòng tròn chia sẻ, trị liệu nghệ thuật")*(DREAMH!$AA$2:$AA$766="Can thiệp chữa lành")*(INDEX(DREAMH!$K$2:$K$766,MATCH(DREAMH!$A$2:$A$766,DREAMH!$A$2:$A$766,0))="Người bán dâm (SW)"))} -> 0 | J39: {=SUMPRODUCT((DREAMH!$D$2:$D$766="Về nhà")*(DREAMH!$B$2:$B$766="F2. Truyền thông, sinh hoạt nhóm, vòng tròn chia sẻ, trị liệu nghệ thuật")*(DREAMH!$AA$2:$AA$766="Can thiệp chữa lành")*(INDEX(DREAMH!$K$2:$K$766,MATCH(DREAMH!$A$2:$A$766,DREAMH!$A$2:$A$766,0))="Nam quan hệ tình dục đồng giới (MSM)"))} -> 0 | K39: x | L39: x | M39: x | N39: x
B40: 6 | C40: Số KH được tham gia can thiệp chữa lành | E40: {=SUMPRODUCT(((DREAMH!$D$2:$D$766="Về nhà")*(DREAMH!$B$2:$B$766="F2. Truyền thông, sinh hoạt nhóm, vòng tròn chia sẻ, trị liệu nghệ thuật")*(DREAMH!$AA$2:$AA$766="Can thiệp chữa lành"))/(COUNTIFS(DREAMH!$A$2:$A$766,DREAMH!$A$2:$A$766,DREAMH!$B$2:$B$766,"F2. Truyền thông, sinh hoạt nhóm, vòng tròn chia sẻ, trị liệu nghệ thuật",DREAMH!$AA$2:$AA$766,"Can thiệp chữa lành")+(COUNTIFS(DREAMH!$A$2:$A$766,DREAMH!$A$2:$A$766,DREAMH!$B$2:$B$766,"F2. Truyền thông, sinh hoạt nhóm, vòng tròn chia sẻ, trị liệu nghệ thuật",DREAMH!$AA$2:$AA$766,"Can thiệp chữa lành")=0)))} -> 0 | F40: {=SUMPRODUCT(((DREAMH!$D$2:$D$766="Về nhà")*(DREAMH!$B$2:$B$766="F2. Truyền thông, sinh hoạt nhóm, vòng tròn chia sẻ, trị liệu nghệ thuật")*(DREAMH!$AA$2:$AA$766="Can thiệp chữa lành"))*(INDEX(DREAMH!$K$2:$K$766,MATCH(DREAMH!$A$2:$A$766,DREAMH!$A$2:$A$766,0))="Người sử dụng ma túy (PUD)")/(COUNTIFS(DREAMH!$A$2:$A$766,DREAMH!$A$2:$A$766,DREAMH!$B$2:$B$766,"F2. Truyền thông, sinh hoạt nhóm, vòng tròn chia sẻ, trị liệu nghệ thuật",DREAMH!$AA$2:$AA$766,"Can thiệp chữa lành")+(COUNTIFS(DREAMH!$A$2:$A$766,DREAMH!$A$2:$A$766,DREAMH!$B$2:$B$766,"F2. Truyền thông, sinh hoạt nhóm, vòng tròn chia sẻ, trị liệu nghệ thuật",DREAMH!$AA$2:$AA$766,"Can thiệp chữa lành")=0)))} -> 0 | G40: {=SUMPRODUCT(((DREAMH!$D$2:$D$766="Về nhà")*(DREAMH!$B$2:$B$766="F2. Truyền thông, sinh hoạt nhóm, vòng tròn chia sẻ, trị liệu nghệ thuật")*(DREAMH!$AA$2:$AA$766="Can thiệp chữa lành"))*(INDEX(DREAMH!$K$2:$K$766,MATCH(DREAMH!$A$2:$A$766,DREAMH!$A$2:$A$766,0))="Người sống chung với HIV (PLHIV)")/(COUNTIFS(DREAMH!$A$2:$A$766,DREAMH!$A$2:$A$766,DREAMH!$B$2:$B$766,"F2. Truyền thông, sinh hoạt nhóm, vòng tròn chia sẻ, trị liệu nghệ thuật",DREAMH!$AA$2:$AA$766,"Can thiệp chữa lành")+(COUNTIFS(DREAMH!$A$2:$A$766,DREAMH!$A$2:$A$766,DREAMH!$B$2:$B$766,"F2. Truyền thông, sinh hoạt nhóm, vòng tròn chia sẻ, trị liệu nghệ thuật",DREAMH!$AA$2:$AA$766,"Can thiệp chữa lành")=0)))} -> 0 | H40: {=SUMPRODUCT(((DREAMH!$D$2:$D$766="Về nhà")*(DREAMH!$B$2:$B$766="F2. Truyền thông, sinh hoạt nhóm, vòng tròn chia sẻ, trị liệu nghệ thuật")*(DREAMH!$AA$2:$AA$766="Can thiệp chữa lành"))*(INDEX(DREAMH!$K$2:$K$766,MATCH(DREAMH!$A$2:$A$766,DREAMH!$A$2:$A$766,0))="Người chuyển giới (TG)")/(COUNTIFS(DREAMH!$A$2:$A$766,DREAMH!$A$2:$A$766,DREAMH!$B$2:$B$766,"F2. Truyền thông, sinh hoạt nhóm, vòng tròn chia sẻ, trị liệu nghệ thuật",DREAMH!$AA$2:$AA$766,"Can thiệp chữa lành")+(COUNTIFS(DREAMH!$A$2:$A$766,DREAMH!$A$2:$A$766,DREAMH!$B$2:$B$766,"F2. Truyền thông, sinh hoạt nhóm, vòng tròn chia sẻ, trị liệu nghệ thuật",DREAMH!$AA$2:$AA$766,"Can thiệp chữa lành")=0)))} -> 0 | I40: {=SUMPRODUCT(((DREAMH!$D$2:$D$766="Về nhà")*(DREAMH!$B$2:$B$766="F2. Truyền thông, sinh hoạt nhóm, vòng tròn chia sẻ, trị liệu nghệ thuật")*(DREAMH!$AA$2:$AA$766="Can thiệp chữa lành"))*(INDEX(DREAMH!$K$2:$K$766,MATCH(DREAMH!$A$2:$A$766,DREAMH!$A$2:$A$766,0))="Người bán dâm (SW)")/(COUNTIFS(DREAMH!$A$2:$A$766,DREAMH!$A$2:$A$766,DREAMH!$B$2:$B$766,"F2. Truyền thông, sinh hoạt nhóm, vòng tròn chia sẻ, trị liệu nghệ thuật",DREAMH!$AA$2:$AA$766,"Can thiệp chữa lành")+(COUNTIFS(DREAMH!$A$2:$A$766,DREAMH!$A$2:$A$766,DREAMH!$B$2:$B$766,"F2. Truyền thông, sinh hoạt nhóm, vòng tròn chia sẻ, trị liệu nghệ thuật",DREAMH!$AA$2:$AA$766,"Can thiệp chữa lành")=0)))} -> 0 | J40: {=SUMPRODUCT(((DREAMH!$D$2:$D$766="Về nhà")*(DREAMH!$B$2:$B$766="F2. Truyền thông, sinh hoạt nhóm, vòng tròn chia sẻ, trị liệu nghệ thuật")*(DREAMH!$AA$2:$AA$766="Can thiệp chữa lành"))*(INDEX(DREAMH!$K$2:$K$766,MATCH(DREAMH!$A$2:$A$766,DREAMH!$A$2:$A$766,0))="Nam quan hệ tình dục đồng giới (MSM)")/(COUNTIFS(DREAMH!$A$2:$A$766,DREAMH!$A$2:$A$766,DREAMH!$B$2:$B$766,"F2. Truyền thông, sinh hoạt nhóm, vòng tròn chia sẻ, trị liệu nghệ thuật",DREAMH!$AA$2:$AA$766,"Can thiệp chữa lành")+(COUNTIFS(DREAMH!$A$2:$A$766,DREAMH!$A$2:$A$766,DREAMH!$B$2:$B$766,"F2. Truyền thông, sinh hoạt nhóm, vòng tròn chia sẻ, trị liệu nghệ thuật",DREAMH!$AA$2:$AA$766,"Can thiệp chữa lành")=0)))} -> 0 | K40: x | L40: x | M40: x | N40: x
B41: V | C41: CAN THIỆP ONLINE
...

Sheet Its T time
C2: BÁO CÁO KẾT QUẢ HOẠT ĐỘNG
C3: Kỳ báo cáo: | F3: Tính theo nhóm KP hay nam/nữ/TG? | K3: Loại báo cáo
B4: # | C4: Thông tin báo cáo | E4: Tổng | F4: PUD | G4: PLHIV | H4: TG | I4: SW | J4: MSM | K4: Tháng | L4: Quý | M4: 6T | N4: 12T | O4: Nguồn số liệu | P4: Notes
B5: I | C5: THÔNG TIN CHUNG
